2017-08-29 18:18:45,590 [Thread-7:140371585648384] [django.request:135] [ERROR]- Internal Server Error: /crawlermanage/settings/
Traceback (most recent call last):
  File "/home/haomao/pythonVir/mainenv/local/lib/python2.7/site-packages/django/core/handlers/exception.py", line 41, in inner
    response = get_response(request)
  File "/home/haomao/pythonVir/mainenv/local/lib/python2.7/site-packages/django/core/handlers/base.py", line 249, in _legacy_get_response
    response = self._get_response(request)
  File "/home/haomao/pythonVir/mainenv/local/lib/python2.7/site-packages/django/core/handlers/base.py", line 198, in _get_response
    "returned None instead." % (callback.__module__, view_name)
ValueError: The view crawlermanage.views.settings didn't return an HttpResponse object. It returned None instead.
2017-08-29 18:18:52,161 [Thread-8:140371585648384] [django.request:135] [ERROR]- Internal Server Error: /crawlermanage/settings/
Traceback (most recent call last):
  File "/home/haomao/pythonVir/mainenv/local/lib/python2.7/site-packages/django/core/handlers/exception.py", line 41, in inner
    response = get_response(request)
  File "/home/haomao/pythonVir/mainenv/local/lib/python2.7/site-packages/django/core/handlers/base.py", line 249, in _legacy_get_response
    response = self._get_response(request)
  File "/home/haomao/pythonVir/mainenv/local/lib/python2.7/site-packages/django/core/handlers/base.py", line 198, in _get_response
    "returned None instead." % (callback.__module__, view_name)
ValueError: The view crawlermanage.views.settings didn't return an HttpResponse object. It returned None instead.
2017-08-29 18:18:53,782 [Thread-9:140371585648384] [django.request:135] [ERROR]- Internal Server Error: /crawlermanage/settings/
Traceback (most recent call last):
  File "/home/haomao/pythonVir/mainenv/local/lib/python2.7/site-packages/django/core/handlers/exception.py", line 41, in inner
    response = get_response(request)
  File "/home/haomao/pythonVir/mainenv/local/lib/python2.7/site-packages/django/core/handlers/base.py", line 249, in _legacy_get_response
    response = self._get_response(request)
  File "/home/haomao/pythonVir/mainenv/local/lib/python2.7/site-packages/django/core/handlers/base.py", line 198, in _get_response
    "returned None instead." % (callback.__module__, view_name)
ValueError: The view crawlermanage.views.settings didn't return an HttpResponse object. It returned None instead.
2017-08-29 18:18:55,024 [Thread-10:140371585648384] [django.request:135] [ERROR]- Internal Server Error: /crawlermanage/settings/
Traceback (most recent call last):
  File "/home/haomao/pythonVir/mainenv/local/lib/python2.7/site-packages/django/core/handlers/exception.py", line 41, in inner
    response = get_response(request)
  File "/home/haomao/pythonVir/mainenv/local/lib/python2.7/site-packages/django/core/handlers/base.py", line 249, in _legacy_get_response
    response = self._get_response(request)
  File "/home/haomao/pythonVir/mainenv/local/lib/python2.7/site-packages/django/core/handlers/base.py", line 198, in _get_response
    "returned None instead." % (callback.__module__, view_name)
ValueError: The view crawlermanage.views.settings didn't return an HttpResponse object. It returned None instead.
2017-08-29 18:18:56,024 [Thread-11:140371585648384] [django.request:135] [ERROR]- Internal Server Error: /crawlermanage/settings/
Traceback (most recent call last):
  File "/home/haomao/pythonVir/mainenv/local/lib/python2.7/site-packages/django/core/handlers/exception.py", line 41, in inner
    response = get_response(request)
  File "/home/haomao/pythonVir/mainenv/local/lib/python2.7/site-packages/django/core/handlers/base.py", line 249, in _legacy_get_response
    response = self._get_response(request)
  File "/home/haomao/pythonVir/mainenv/local/lib/python2.7/site-packages/django/core/handlers/base.py", line 198, in _get_response
    "returned None instead." % (callback.__module__, view_name)
ValueError: The view crawlermanage.views.settings didn't return an HttpResponse object. It returned None instead.
2017-08-29 18:19:01,739 [Thread-12:140371585648384] [django.request:135] [ERROR]- Internal Server Error: /crawlermanage/settings/
Traceback (most recent call last):
  File "/home/haomao/pythonVir/mainenv/local/lib/python2.7/site-packages/django/core/handlers/exception.py", line 41, in inner
    response = get_response(request)
  File "/home/haomao/pythonVir/mainenv/local/lib/python2.7/site-packages/django/core/handlers/base.py", line 249, in _legacy_get_response
    response = self._get_response(request)
  File "/home/haomao/pythonVir/mainenv/local/lib/python2.7/site-packages/django/core/handlers/base.py", line 198, in _get_response
    "returned None instead." % (callback.__module__, view_name)
ValueError: The view crawlermanage.views.settings didn't return an HttpResponse object. It returned None instead.
2017-08-29 18:19:02,592 [Thread-13:140371585648384] [django.request:135] [ERROR]- Internal Server Error: /crawlermanage/settings/
Traceback (most recent call last):
  File "/home/haomao/pythonVir/mainenv/local/lib/python2.7/site-packages/django/core/handlers/exception.py", line 41, in inner
    response = get_response(request)
  File "/home/haomao/pythonVir/mainenv/local/lib/python2.7/site-packages/django/core/handlers/base.py", line 249, in _legacy_get_response
    response = self._get_response(request)
  File "/home/haomao/pythonVir/mainenv/local/lib/python2.7/site-packages/django/core/handlers/base.py", line 198, in _get_response
    "returned None instead." % (callback.__module__, view_name)
ValueError: The view crawlermanage.views.settings didn't return an HttpResponse object. It returned None instead.
2017-08-29 18:19:05,561 [Thread-14:140371585648384] [django.request:135] [ERROR]- Internal Server Error: /crawlermanage/settings/
Traceback (most recent call last):
  File "/home/haomao/pythonVir/mainenv/local/lib/python2.7/site-packages/django/core/handlers/exception.py", line 41, in inner
    response = get_response(request)
  File "/home/haomao/pythonVir/mainenv/local/lib/python2.7/site-packages/django/core/handlers/base.py", line 249, in _legacy_get_response
    response = self._get_response(request)
  File "/home/haomao/pythonVir/mainenv/local/lib/python2.7/site-packages/django/core/handlers/base.py", line 198, in _get_response
    "returned None instead." % (callback.__module__, view_name)
ValueError: The view crawlermanage.views.settings didn't return an HttpResponse object. It returned None instead.
2017-08-29 18:19:06,304 [Thread-15:140371585648384] [django.request:135] [ERROR]- Internal Server Error: /crawlermanage/settings/
Traceback (most recent call last):
  File "/home/haomao/pythonVir/mainenv/local/lib/python2.7/site-packages/django/core/handlers/exception.py", line 41, in inner
    response = get_response(request)
  File "/home/haomao/pythonVir/mainenv/local/lib/python2.7/site-packages/django/core/handlers/base.py", line 249, in _legacy_get_response
    response = self._get_response(request)
  File "/home/haomao/pythonVir/mainenv/local/lib/python2.7/site-packages/django/core/handlers/base.py", line 198, in _get_response
    "returned None instead." % (callback.__module__, view_name)
ValueError: The view crawlermanage.views.settings didn't return an HttpResponse object. It returned None instead.
2017-08-29 18:19:14,265 [Thread-16:140371585648384] [django.request:135] [ERROR]- Internal Server Error: /crawlermanage/settings/
Traceback (most recent call last):
  File "/home/haomao/pythonVir/mainenv/local/lib/python2.7/site-packages/django/core/handlers/exception.py", line 41, in inner
    response = get_response(request)
  File "/home/haomao/pythonVir/mainenv/local/lib/python2.7/site-packages/django/core/handlers/base.py", line 249, in _legacy_get_response
    response = self._get_response(request)
  File "/home/haomao/pythonVir/mainenv/local/lib/python2.7/site-packages/django/core/handlers/base.py", line 198, in _get_response
    "returned None instead." % (callback.__module__, view_name)
ValueError: The view crawlermanage.views.settings didn't return an HttpResponse object. It returned None instead.
2017-08-29 18:19:15,608 [Thread-17:140371585648384] [django.request:135] [ERROR]- Internal Server Error: /crawlermanage/settings/
Traceback (most recent call last):
  File "/home/haomao/pythonVir/mainenv/local/lib/python2.7/site-packages/django/core/handlers/exception.py", line 41, in inner
    response = get_response(request)
  File "/home/haomao/pythonVir/mainenv/local/lib/python2.7/site-packages/django/core/handlers/base.py", line 249, in _legacy_get_response
    response = self._get_response(request)
  File "/home/haomao/pythonVir/mainenv/local/lib/python2.7/site-packages/django/core/handlers/base.py", line 198, in _get_response
    "returned None instead." % (callback.__module__, view_name)
ValueError: The view crawlermanage.views.settings didn't return an HttpResponse object. It returned None instead.
2017-08-29 18:19:16,816 [Thread-18:140371585648384] [django.request:135] [ERROR]- Internal Server Error: /crawlermanage/settings/
Traceback (most recent call last):
  File "/home/haomao/pythonVir/mainenv/local/lib/python2.7/site-packages/django/core/handlers/exception.py", line 41, in inner
    response = get_response(request)
  File "/home/haomao/pythonVir/mainenv/local/lib/python2.7/site-packages/django/core/handlers/base.py", line 249, in _legacy_get_response
    response = self._get_response(request)
  File "/home/haomao/pythonVir/mainenv/local/lib/python2.7/site-packages/django/core/handlers/base.py", line 198, in _get_response
    "returned None instead." % (callback.__module__, view_name)
ValueError: The view crawlermanage.views.settings didn't return an HttpResponse object. It returned None instead.
2017-08-29 18:19:17,867 [Thread-19:140371585648384] [django.request:135] [ERROR]- Internal Server Error: /crawlermanage/settings/
Traceback (most recent call last):
  File "/home/haomao/pythonVir/mainenv/local/lib/python2.7/site-packages/django/core/handlers/exception.py", line 41, in inner
    response = get_response(request)
  File "/home/haomao/pythonVir/mainenv/local/lib/python2.7/site-packages/django/core/handlers/base.py", line 249, in _legacy_get_response
    response = self._get_response(request)
  File "/home/haomao/pythonVir/mainenv/local/lib/python2.7/site-packages/django/core/handlers/base.py", line 198, in _get_response
    "returned None instead." % (callback.__module__, view_name)
ValueError: The view crawlermanage.views.settings didn't return an HttpResponse object. It returned None instead.
2017-08-29 18:19:19,033 [Thread-20:140371585648384] [django.request:135] [ERROR]- Internal Server Error: /crawlermanage/settings/
Traceback (most recent call last):
  File "/home/haomao/pythonVir/mainenv/local/lib/python2.7/site-packages/django/core/handlers/exception.py", line 41, in inner
    response = get_response(request)
  File "/home/haomao/pythonVir/mainenv/local/lib/python2.7/site-packages/django/core/handlers/base.py", line 249, in _legacy_get_response
    response = self._get_response(request)
  File "/home/haomao/pythonVir/mainenv/local/lib/python2.7/site-packages/django/core/handlers/base.py", line 198, in _get_response
    "returned None instead." % (callback.__module__, view_name)
ValueError: The view crawlermanage.views.settings didn't return an HttpResponse object. It returned None instead.
2017-08-29 18:19:20,247 [Thread-21:140371585648384] [django.request:135] [ERROR]- Internal Server Error: /crawlermanage/settings/
Traceback (most recent call last):
  File "/home/haomao/pythonVir/mainenv/local/lib/python2.7/site-packages/django/core/handlers/exception.py", line 41, in inner
    response = get_response(request)
  File "/home/haomao/pythonVir/mainenv/local/lib/python2.7/site-packages/django/core/handlers/base.py", line 249, in _legacy_get_response
    response = self._get_response(request)
  File "/home/haomao/pythonVir/mainenv/local/lib/python2.7/site-packages/django/core/handlers/base.py", line 198, in _get_response
    "returned None instead." % (callback.__module__, view_name)
ValueError: The view crawlermanage.views.settings didn't return an HttpResponse object. It returned None instead.
2017-08-29 18:19:21,249 [Thread-22:140371585648384] [django.request:135] [ERROR]- Internal Server Error: /crawlermanage/settings/
Traceback (most recent call last):
  File "/home/haomao/pythonVir/mainenv/local/lib/python2.7/site-packages/django/core/handlers/exception.py", line 41, in inner
    response = get_response(request)
  File "/home/haomao/pythonVir/mainenv/local/lib/python2.7/site-packages/django/core/handlers/base.py", line 249, in _legacy_get_response
    response = self._get_response(request)
  File "/home/haomao/pythonVir/mainenv/local/lib/python2.7/site-packages/django/core/handlers/base.py", line 198, in _get_response
    "returned None instead." % (callback.__module__, view_name)
ValueError: The view crawlermanage.views.settings didn't return an HttpResponse object. It returned None instead.
2017-08-29 18:19:47,025 [Thread-23:140371585648384] [django.request:135] [ERROR]- Internal Server Error: /crawlermanage/settings/
Traceback (most recent call last):
  File "/home/haomao/pythonVir/mainenv/local/lib/python2.7/site-packages/django/core/handlers/exception.py", line 41, in inner
    response = get_response(request)
  File "/home/haomao/pythonVir/mainenv/local/lib/python2.7/site-packages/django/core/handlers/base.py", line 249, in _legacy_get_response
    response = self._get_response(request)
  File "/home/haomao/pythonVir/mainenv/local/lib/python2.7/site-packages/django/core/handlers/base.py", line 198, in _get_response
    "returned None instead." % (callback.__module__, view_name)
ValueError: The view crawlermanage.views.settings didn't return an HttpResponse object. It returned None instead.
2017-08-29 18:26:43,034 [Thread-37:140371585648384] [django.request:135] [ERROR]- Internal Server Error: /crawlermanage/settings/
Traceback (most recent call last):
  File "/home/haomao/pythonVir/mainenv/local/lib/python2.7/site-packages/django/core/handlers/exception.py", line 41, in inner
    response = get_response(request)
  File "/home/haomao/pythonVir/mainenv/local/lib/python2.7/site-packages/django/core/handlers/base.py", line 249, in _legacy_get_response
    response = self._get_response(request)
  File "/home/haomao/pythonVir/mainenv/local/lib/python2.7/site-packages/django/core/handlers/base.py", line 198, in _get_response
    "returned None instead." % (callback.__module__, view_name)
ValueError: The view crawlermanage.views.settings didn't return an HttpResponse object. It returned None instead.
2017-08-29 18:26:44,493 [Thread-38:140371585648384] [django.request:152] [WARNING]- Not Found: /favicon.ico
2017-08-29 19:13:03,511 [Thread-41:140371585648384] [django.request:152] [WARNING]- Not Found: /favicon.ico
2017-08-29 19:32:34,276 [Thread-48:140371585648384] [django.request:135] [ERROR]- Internal Server Error: /crawlermanage/settings/
Traceback (most recent call last):
  File "/home/haomao/pythonVir/mainenv/local/lib/python2.7/site-packages/django/core/handlers/exception.py", line 41, in inner
    response = get_response(request)
  File "/home/haomao/pythonVir/mainenv/local/lib/python2.7/site-packages/django/core/handlers/base.py", line 249, in _legacy_get_response
    response = self._get_response(request)
  File "/home/haomao/pythonVir/mainenv/local/lib/python2.7/site-packages/django/core/handlers/base.py", line 198, in _get_response
    "returned None instead." % (callback.__module__, view_name)
ValueError: The view crawlermanage.views.settings didn't return an HttpResponse object. It returned None instead.
2017-08-29 20:35:36,849 [Thread-13:139933347096320] [django.request:152] [WARNING]- Not Found: /Search/Index
2017-08-29 20:37:22,972 [Thread-18:139933338703616] [django.request:152] [WARNING]- Not Found: /Search/Index
2017-08-29 20:42:55,334 [Thread-5:139782256486144] [django.request:152] [WARNING]- Not Found: /Search/Index
2017-08-29 20:53:29,408 [Thread-10:140236194227968] [django.request:152] [WARNING]- Not Found: /Search/Index
2017-08-29 21:06:30,254 [Thread-3:139945661589248] [django.request:135] [ERROR]- Internal Server Error: /crawlermanage/domainautocomplete/
Traceback (most recent call last):
  File "/home/haomao/pythonVir/mainenv/local/lib/python2.7/site-packages/django/core/handlers/exception.py", line 41, in inner
    response = get_response(request)
  File "/home/haomao/pythonVir/mainenv/local/lib/python2.7/site-packages/django/core/handlers/base.py", line 249, in _legacy_get_response
    response = self._get_response(request)
  File "/home/haomao/pythonVir/mainenv/local/lib/python2.7/site-packages/django/core/handlers/base.py", line 187, in _get_response
    response = self.process_exception_by_middleware(e, request)
  File "/home/haomao/pythonVir/mainenv/local/lib/python2.7/site-packages/django/core/handlers/base.py", line 185, in _get_response
    response = wrapped_callback(request, *callback_args, **callback_kwargs)
  File "/home/haomao/Desktop/project/geowind_crawler/crawlermanage/views.py", line 585, in domain_autocomplete
    return HttpResponse(json.dump(ret))
TypeError: dump() takes at least 2 arguments (1 given)
2017-08-29 21:06:41,730 [Thread-4:139945661589248] [django.request:135] [ERROR]- Internal Server Error: /crawlermanage/domainautocomplete/
Traceback (most recent call last):
  File "/home/haomao/pythonVir/mainenv/local/lib/python2.7/site-packages/django/core/handlers/exception.py", line 41, in inner
    response = get_response(request)
  File "/home/haomao/pythonVir/mainenv/local/lib/python2.7/site-packages/django/core/handlers/base.py", line 249, in _legacy_get_response
    response = self._get_response(request)
  File "/home/haomao/pythonVir/mainenv/local/lib/python2.7/site-packages/django/core/handlers/base.py", line 187, in _get_response
    response = self.process_exception_by_middleware(e, request)
  File "/home/haomao/pythonVir/mainenv/local/lib/python2.7/site-packages/django/core/handlers/base.py", line 185, in _get_response
    response = wrapped_callback(request, *callback_args, **callback_kwargs)
  File "/home/haomao/Desktop/project/geowind_crawler/crawlermanage/views.py", line 585, in domain_autocomplete
    return HttpResponse(json.dump(ret))
TypeError: dump() takes at least 2 arguments (1 given)
2017-08-29 21:07:10,056 [Thread-5:139945661589248] [django.request:135] [ERROR]- Internal Server Error: /crawlermanage/domainautocomplete/
Traceback (most recent call last):
  File "/home/haomao/pythonVir/mainenv/local/lib/python2.7/site-packages/django/core/handlers/exception.py", line 41, in inner
    response = get_response(request)
  File "/home/haomao/pythonVir/mainenv/local/lib/python2.7/site-packages/django/core/handlers/base.py", line 249, in _legacy_get_response
    response = self._get_response(request)
  File "/home/haomao/pythonVir/mainenv/local/lib/python2.7/site-packages/django/core/handlers/base.py", line 187, in _get_response
    response = self.process_exception_by_middleware(e, request)
  File "/home/haomao/pythonVir/mainenv/local/lib/python2.7/site-packages/django/core/handlers/base.py", line 185, in _get_response
    response = wrapped_callback(request, *callback_args, **callback_kwargs)
  File "/home/haomao/Desktop/project/geowind_crawler/crawlermanage/views.py", line 585, in domain_autocomplete
    return HttpResponse(json.dump(ret))
TypeError: dump() takes at least 2 arguments (1 given)
2017-08-29 21:07:10,262 [Thread-6:139945661589248] [django.request:135] [ERROR]- Internal Server Error: /crawlermanage/domainautocomplete/
Traceback (most recent call last):
  File "/home/haomao/pythonVir/mainenv/local/lib/python2.7/site-packages/django/core/handlers/exception.py", line 41, in inner
    response = get_response(request)
  File "/home/haomao/pythonVir/mainenv/local/lib/python2.7/site-packages/django/core/handlers/base.py", line 249, in _legacy_get_response
    response = self._get_response(request)
  File "/home/haomao/pythonVir/mainenv/local/lib/python2.7/site-packages/django/core/handlers/base.py", line 187, in _get_response
    response = self.process_exception_by_middleware(e, request)
  File "/home/haomao/pythonVir/mainenv/local/lib/python2.7/site-packages/django/core/handlers/base.py", line 185, in _get_response
    response = wrapped_callback(request, *callback_args, **callback_kwargs)
  File "/home/haomao/Desktop/project/geowind_crawler/crawlermanage/views.py", line 585, in domain_autocomplete
    return HttpResponse(json.dump(ret))
TypeError: dump() takes at least 2 arguments (1 given)
2017-08-29 21:07:11,798 [Thread-7:139945661589248] [django.request:135] [ERROR]- Internal Server Error: /crawlermanage/domainautocomplete/
Traceback (most recent call last):
  File "/home/haomao/pythonVir/mainenv/local/lib/python2.7/site-packages/django/core/handlers/exception.py", line 41, in inner
    response = get_response(request)
  File "/home/haomao/pythonVir/mainenv/local/lib/python2.7/site-packages/django/core/handlers/base.py", line 249, in _legacy_get_response
    response = self._get_response(request)
  File "/home/haomao/pythonVir/mainenv/local/lib/python2.7/site-packages/django/core/handlers/base.py", line 187, in _get_response
    response = self.process_exception_by_middleware(e, request)
  File "/home/haomao/pythonVir/mainenv/local/lib/python2.7/site-packages/django/core/handlers/base.py", line 185, in _get_response
    response = wrapped_callback(request, *callback_args, **callback_kwargs)
  File "/home/haomao/Desktop/project/geowind_crawler/crawlermanage/views.py", line 585, in domain_autocomplete
    return HttpResponse(json.dump(ret))
TypeError: dump() takes at least 2 arguments (1 given)
2017-08-29 21:07:12,005 [Thread-8:139945661589248] [django.request:135] [ERROR]- Internal Server Error: /crawlermanage/domainautocomplete/
Traceback (most recent call last):
  File "/home/haomao/pythonVir/mainenv/local/lib/python2.7/site-packages/django/core/handlers/exception.py", line 41, in inner
    response = get_response(request)
  File "/home/haomao/pythonVir/mainenv/local/lib/python2.7/site-packages/django/core/handlers/base.py", line 249, in _legacy_get_response
    response = self._get_response(request)
  File "/home/haomao/pythonVir/mainenv/local/lib/python2.7/site-packages/django/core/handlers/base.py", line 187, in _get_response
    response = self.process_exception_by_middleware(e, request)
  File "/home/haomao/pythonVir/mainenv/local/lib/python2.7/site-packages/django/core/handlers/base.py", line 185, in _get_response
    response = wrapped_callback(request, *callback_args, **callback_kwargs)
  File "/home/haomao/Desktop/project/geowind_crawler/crawlermanage/views.py", line 585, in domain_autocomplete
    return HttpResponse(json.dump(ret))
TypeError: dump() takes at least 2 arguments (1 given)
2017-08-29 21:07:12,190 [Thread-9:139945661589248] [django.request:135] [ERROR]- Internal Server Error: /crawlermanage/domainautocomplete/
Traceback (most recent call last):
  File "/home/haomao/pythonVir/mainenv/local/lib/python2.7/site-packages/django/core/handlers/exception.py", line 41, in inner
    response = get_response(request)
  File "/home/haomao/pythonVir/mainenv/local/lib/python2.7/site-packages/django/core/handlers/base.py", line 249, in _legacy_get_response
    response = self._get_response(request)
  File "/home/haomao/pythonVir/mainenv/local/lib/python2.7/site-packages/django/core/handlers/base.py", line 187, in _get_response
    response = self.process_exception_by_middleware(e, request)
  File "/home/haomao/pythonVir/mainenv/local/lib/python2.7/site-packages/django/core/handlers/base.py", line 185, in _get_response
    response = wrapped_callback(request, *callback_args, **callback_kwargs)
  File "/home/haomao/Desktop/project/geowind_crawler/crawlermanage/views.py", line 585, in domain_autocomplete
    return HttpResponse(json.dump(ret))
TypeError: dump() takes at least 2 arguments (1 given)
2017-08-29 21:07:26,368 [Thread-10:139945661589248] [django.request:135] [ERROR]- Internal Server Error: /crawlermanage/domainautocomplete/
Traceback (most recent call last):
  File "/home/haomao/pythonVir/mainenv/local/lib/python2.7/site-packages/django/core/handlers/exception.py", line 41, in inner
    response = get_response(request)
  File "/home/haomao/pythonVir/mainenv/local/lib/python2.7/site-packages/django/core/handlers/base.py", line 249, in _legacy_get_response
    response = self._get_response(request)
  File "/home/haomao/pythonVir/mainenv/local/lib/python2.7/site-packages/django/core/handlers/base.py", line 187, in _get_response
    response = self.process_exception_by_middleware(e, request)
  File "/home/haomao/pythonVir/mainenv/local/lib/python2.7/site-packages/django/core/handlers/base.py", line 185, in _get_response
    response = wrapped_callback(request, *callback_args, **callback_kwargs)
  File "/home/haomao/Desktop/project/geowind_crawler/crawlermanage/views.py", line 585, in domain_autocomplete
    return HttpResponse(json.dump(ret))
TypeError: dump() takes at least 2 arguments (1 given)
2017-08-29 21:07:27,270 [Thread-11:139945661589248] [django.request:135] [ERROR]- Internal Server Error: /crawlermanage/domainautocomplete/
Traceback (most recent call last):
  File "/home/haomao/pythonVir/mainenv/local/lib/python2.7/site-packages/django/core/handlers/exception.py", line 41, in inner
    response = get_response(request)
  File "/home/haomao/pythonVir/mainenv/local/lib/python2.7/site-packages/django/core/handlers/base.py", line 249, in _legacy_get_response
    response = self._get_response(request)
  File "/home/haomao/pythonVir/mainenv/local/lib/python2.7/site-packages/django/core/handlers/base.py", line 187, in _get_response
    response = self.process_exception_by_middleware(e, request)
  File "/home/haomao/pythonVir/mainenv/local/lib/python2.7/site-packages/django/core/handlers/base.py", line 185, in _get_response
    response = wrapped_callback(request, *callback_args, **callback_kwargs)
  File "/home/haomao/Desktop/project/geowind_crawler/crawlermanage/views.py", line 585, in domain_autocomplete
    return HttpResponse(json.dump(ret))
TypeError: dump() takes at least 2 arguments (1 given)
2017-08-29 21:07:28,969 [Thread-12:139945661589248] [django.request:135] [ERROR]- Internal Server Error: /crawlermanage/domainautocomplete/
Traceback (most recent call last):
  File "/home/haomao/pythonVir/mainenv/local/lib/python2.7/site-packages/django/core/handlers/exception.py", line 41, in inner
    response = get_response(request)
  File "/home/haomao/pythonVir/mainenv/local/lib/python2.7/site-packages/django/core/handlers/base.py", line 249, in _legacy_get_response
    response = self._get_response(request)
  File "/home/haomao/pythonVir/mainenv/local/lib/python2.7/site-packages/django/core/handlers/base.py", line 187, in _get_response
    response = self.process_exception_by_middleware(e, request)
  File "/home/haomao/pythonVir/mainenv/local/lib/python2.7/site-packages/django/core/handlers/base.py", line 185, in _get_response
    response = wrapped_callback(request, *callback_args, **callback_kwargs)
  File "/home/haomao/Desktop/project/geowind_crawler/crawlermanage/views.py", line 585, in domain_autocomplete
    return HttpResponse(json.dump(ret))
TypeError: dump() takes at least 2 arguments (1 given)
2017-08-29 21:07:29,182 [Thread-13:139945661589248] [django.request:135] [ERROR]- Internal Server Error: /crawlermanage/domainautocomplete/
Traceback (most recent call last):
  File "/home/haomao/pythonVir/mainenv/local/lib/python2.7/site-packages/django/core/handlers/exception.py", line 41, in inner
    response = get_response(request)
  File "/home/haomao/pythonVir/mainenv/local/lib/python2.7/site-packages/django/core/handlers/base.py", line 249, in _legacy_get_response
    response = self._get_response(request)
  File "/home/haomao/pythonVir/mainenv/local/lib/python2.7/site-packages/django/core/handlers/base.py", line 187, in _get_response
    response = self.process_exception_by_middleware(e, request)
  File "/home/haomao/pythonVir/mainenv/local/lib/python2.7/site-packages/django/core/handlers/base.py", line 185, in _get_response
    response = wrapped_callback(request, *callback_args, **callback_kwargs)
  File "/home/haomao/Desktop/project/geowind_crawler/crawlermanage/views.py", line 585, in domain_autocomplete
    return HttpResponse(json.dump(ret))
TypeError: dump() takes at least 2 arguments (1 given)
2017-08-29 21:07:29,625 [Thread-14:139945661589248] [django.request:135] [ERROR]- Internal Server Error: /crawlermanage/domainautocomplete/
Traceback (most recent call last):
  File "/home/haomao/pythonVir/mainenv/local/lib/python2.7/site-packages/django/core/handlers/exception.py", line 41, in inner
    response = get_response(request)
  File "/home/haomao/pythonVir/mainenv/local/lib/python2.7/site-packages/django/core/handlers/base.py", line 249, in _legacy_get_response
    response = self._get_response(request)
  File "/home/haomao/pythonVir/mainenv/local/lib/python2.7/site-packages/django/core/handlers/base.py", line 187, in _get_response
    response = self.process_exception_by_middleware(e, request)
  File "/home/haomao/pythonVir/mainenv/local/lib/python2.7/site-packages/django/core/handlers/base.py", line 185, in _get_response
    response = wrapped_callback(request, *callback_args, **callback_kwargs)
  File "/home/haomao/Desktop/project/geowind_crawler/crawlermanage/views.py", line 585, in domain_autocomplete
    return HttpResponse(json.dump(ret))
TypeError: dump() takes at least 2 arguments (1 given)
2017-08-29 21:07:30,026 [Thread-15:139945661589248] [django.request:135] [ERROR]- Internal Server Error: /crawlermanage/domainautocomplete/
Traceback (most recent call last):
  File "/home/haomao/pythonVir/mainenv/local/lib/python2.7/site-packages/django/core/handlers/exception.py", line 41, in inner
    response = get_response(request)
  File "/home/haomao/pythonVir/mainenv/local/lib/python2.7/site-packages/django/core/handlers/base.py", line 249, in _legacy_get_response
    response = self._get_response(request)
  File "/home/haomao/pythonVir/mainenv/local/lib/python2.7/site-packages/django/core/handlers/base.py", line 187, in _get_response
    response = self.process_exception_by_middleware(e, request)
  File "/home/haomao/pythonVir/mainenv/local/lib/python2.7/site-packages/django/core/handlers/base.py", line 185, in _get_response
    response = wrapped_callback(request, *callback_args, **callback_kwargs)
  File "/home/haomao/Desktop/project/geowind_crawler/crawlermanage/views.py", line 585, in domain_autocomplete
    return HttpResponse(json.dump(ret))
TypeError: dump() takes at least 2 arguments (1 given)
2017-08-29 21:07:30,222 [Thread-16:139945661589248] [django.request:135] [ERROR]- Internal Server Error: /crawlermanage/domainautocomplete/
Traceback (most recent call last):
  File "/home/haomao/pythonVir/mainenv/local/lib/python2.7/site-packages/django/core/handlers/exception.py", line 41, in inner
    response = get_response(request)
  File "/home/haomao/pythonVir/mainenv/local/lib/python2.7/site-packages/django/core/handlers/base.py", line 249, in _legacy_get_response
    response = self._get_response(request)
  File "/home/haomao/pythonVir/mainenv/local/lib/python2.7/site-packages/django/core/handlers/base.py", line 187, in _get_response
    response = self.process_exception_by_middleware(e, request)
  File "/home/haomao/pythonVir/mainenv/local/lib/python2.7/site-packages/django/core/handlers/base.py", line 185, in _get_response
    response = wrapped_callback(request, *callback_args, **callback_kwargs)
  File "/home/haomao/Desktop/project/geowind_crawler/crawlermanage/views.py", line 585, in domain_autocomplete
    return HttpResponse(json.dump(ret))
TypeError: dump() takes at least 2 arguments (1 given)
2017-08-29 21:07:30,880 [Thread-17:139945661589248] [django.request:135] [ERROR]- Internal Server Error: /crawlermanage/domainautocomplete/
Traceback (most recent call last):
  File "/home/haomao/pythonVir/mainenv/local/lib/python2.7/site-packages/django/core/handlers/exception.py", line 41, in inner
    response = get_response(request)
  File "/home/haomao/pythonVir/mainenv/local/lib/python2.7/site-packages/django/core/handlers/base.py", line 249, in _legacy_get_response
    response = self._get_response(request)
  File "/home/haomao/pythonVir/mainenv/local/lib/python2.7/site-packages/django/core/handlers/base.py", line 187, in _get_response
    response = self.process_exception_by_middleware(e, request)
  File "/home/haomao/pythonVir/mainenv/local/lib/python2.7/site-packages/django/core/handlers/base.py", line 185, in _get_response
    response = wrapped_callback(request, *callback_args, **callback_kwargs)
  File "/home/haomao/Desktop/project/geowind_crawler/crawlermanage/views.py", line 585, in domain_autocomplete
    return HttpResponse(json.dump(ret))
TypeError: dump() takes at least 2 arguments (1 given)
2017-08-29 21:07:31,065 [Thread-18:139945661589248] [django.request:135] [ERROR]- Internal Server Error: /crawlermanage/domainautocomplete/
Traceback (most recent call last):
  File "/home/haomao/pythonVir/mainenv/local/lib/python2.7/site-packages/django/core/handlers/exception.py", line 41, in inner
    response = get_response(request)
  File "/home/haomao/pythonVir/mainenv/local/lib/python2.7/site-packages/django/core/handlers/base.py", line 249, in _legacy_get_response
    response = self._get_response(request)
  File "/home/haomao/pythonVir/mainenv/local/lib/python2.7/site-packages/django/core/handlers/base.py", line 187, in _get_response
    response = self.process_exception_by_middleware(e, request)
  File "/home/haomao/pythonVir/mainenv/local/lib/python2.7/site-packages/django/core/handlers/base.py", line 185, in _get_response
    response = wrapped_callback(request, *callback_args, **callback_kwargs)
  File "/home/haomao/Desktop/project/geowind_crawler/crawlermanage/views.py", line 585, in domain_autocomplete
    return HttpResponse(json.dump(ret))
TypeError: dump() takes at least 2 arguments (1 given)
2017-08-29 21:07:31,253 [Thread-19:139945661589248] [django.request:135] [ERROR]- Internal Server Error: /crawlermanage/domainautocomplete/
Traceback (most recent call last):
  File "/home/haomao/pythonVir/mainenv/local/lib/python2.7/site-packages/django/core/handlers/exception.py", line 41, in inner
    response = get_response(request)
  File "/home/haomao/pythonVir/mainenv/local/lib/python2.7/site-packages/django/core/handlers/base.py", line 249, in _legacy_get_response
    response = self._get_response(request)
  File "/home/haomao/pythonVir/mainenv/local/lib/python2.7/site-packages/django/core/handlers/base.py", line 187, in _get_response
    response = self.process_exception_by_middleware(e, request)
  File "/home/haomao/pythonVir/mainenv/local/lib/python2.7/site-packages/django/core/handlers/base.py", line 185, in _get_response
    response = wrapped_callback(request, *callback_args, **callback_kwargs)
  File "/home/haomao/Desktop/project/geowind_crawler/crawlermanage/views.py", line 585, in domain_autocomplete
    return HttpResponse(json.dump(ret))
TypeError: dump() takes at least 2 arguments (1 given)
2017-08-29 21:07:31,724 [Thread-20:139945661589248] [django.request:135] [ERROR]- Internal Server Error: /crawlermanage/domainautocomplete/
Traceback (most recent call last):
  File "/home/haomao/pythonVir/mainenv/local/lib/python2.7/site-packages/django/core/handlers/exception.py", line 41, in inner
    response = get_response(request)
  File "/home/haomao/pythonVir/mainenv/local/lib/python2.7/site-packages/django/core/handlers/base.py", line 249, in _legacy_get_response
    response = self._get_response(request)
  File "/home/haomao/pythonVir/mainenv/local/lib/python2.7/site-packages/django/core/handlers/base.py", line 187, in _get_response
    response = self.process_exception_by_middleware(e, request)
  File "/home/haomao/pythonVir/mainenv/local/lib/python2.7/site-packages/django/core/handlers/base.py", line 185, in _get_response
    response = wrapped_callback(request, *callback_args, **callback_kwargs)
  File "/home/haomao/Desktop/project/geowind_crawler/crawlermanage/views.py", line 585, in domain_autocomplete
    return HttpResponse(json.dump(ret))
TypeError: dump() takes at least 2 arguments (1 given)
2017-08-29 21:07:31,900 [Thread-21:139945661589248] [django.request:135] [ERROR]- Internal Server Error: /crawlermanage/domainautocomplete/
Traceback (most recent call last):
  File "/home/haomao/pythonVir/mainenv/local/lib/python2.7/site-packages/django/core/handlers/exception.py", line 41, in inner
    response = get_response(request)
  File "/home/haomao/pythonVir/mainenv/local/lib/python2.7/site-packages/django/core/handlers/base.py", line 249, in _legacy_get_response
    response = self._get_response(request)
  File "/home/haomao/pythonVir/mainenv/local/lib/python2.7/site-packages/django/core/handlers/base.py", line 187, in _get_response
    response = self.process_exception_by_middleware(e, request)
  File "/home/haomao/pythonVir/mainenv/local/lib/python2.7/site-packages/django/core/handlers/base.py", line 185, in _get_response
    response = wrapped_callback(request, *callback_args, **callback_kwargs)
  File "/home/haomao/Desktop/project/geowind_crawler/crawlermanage/views.py", line 585, in domain_autocomplete
    return HttpResponse(json.dump(ret))
TypeError: dump() takes at least 2 arguments (1 given)
2017-08-29 21:09:07,023 [Thread-3:140387309479680] [django.request:135] [ERROR]- Internal Server Error: /crawlermanage/domainautocomplete/
Traceback (most recent call last):
  File "/home/haomao/pythonVir/mainenv/local/lib/python2.7/site-packages/django/core/handlers/exception.py", line 41, in inner
    response = get_response(request)
  File "/home/haomao/pythonVir/mainenv/local/lib/python2.7/site-packages/django/core/handlers/base.py", line 249, in _legacy_get_response
    response = self._get_response(request)
  File "/home/haomao/pythonVir/mainenv/local/lib/python2.7/site-packages/django/core/handlers/base.py", line 187, in _get_response
    response = self.process_exception_by_middleware(e, request)
  File "/home/haomao/pythonVir/mainenv/local/lib/python2.7/site-packages/django/core/handlers/base.py", line 185, in _get_response
    response = wrapped_callback(request, *callback_args, **callback_kwargs)
  File "/home/haomao/Desktop/project/geowind_crawler/crawlermanage/views.py", line 585, in domain_autocomplete
    return HttpResponse(json.dump(ret))
TypeError: dump() takes at least 2 arguments (1 given)
2017-08-29 21:09:07,031 [Thread-4:140387300300544] [django.request:135] [ERROR]- Internal Server Error: /crawlermanage/domainautocomplete/
Traceback (most recent call last):
  File "/home/haomao/pythonVir/mainenv/local/lib/python2.7/site-packages/django/core/handlers/exception.py", line 41, in inner
    response = get_response(request)
  File "/home/haomao/pythonVir/mainenv/local/lib/python2.7/site-packages/django/core/handlers/base.py", line 249, in _legacy_get_response
    response = self._get_response(request)
  File "/home/haomao/pythonVir/mainenv/local/lib/python2.7/site-packages/django/core/handlers/base.py", line 187, in _get_response
    response = self.process_exception_by_middleware(e, request)
  File "/home/haomao/pythonVir/mainenv/local/lib/python2.7/site-packages/django/core/handlers/base.py", line 185, in _get_response
    response = wrapped_callback(request, *callback_args, **callback_kwargs)
  File "/home/haomao/Desktop/project/geowind_crawler/crawlermanage/views.py", line 585, in domain_autocomplete
    return HttpResponse(json.dump(ret))
TypeError: dump() takes at least 2 arguments (1 given)
2017-08-29 21:09:10,463 [Thread-5:140387300300544] [django.request:135] [ERROR]- Internal Server Error: /crawlermanage/domainautocomplete/
Traceback (most recent call last):
  File "/home/haomao/pythonVir/mainenv/local/lib/python2.7/site-packages/django/core/handlers/exception.py", line 41, in inner
    response = get_response(request)
  File "/home/haomao/pythonVir/mainenv/local/lib/python2.7/site-packages/django/core/handlers/base.py", line 249, in _legacy_get_response
    response = self._get_response(request)
  File "/home/haomao/pythonVir/mainenv/local/lib/python2.7/site-packages/django/core/handlers/base.py", line 187, in _get_response
    response = self.process_exception_by_middleware(e, request)
  File "/home/haomao/pythonVir/mainenv/local/lib/python2.7/site-packages/django/core/handlers/base.py", line 185, in _get_response
    response = wrapped_callback(request, *callback_args, **callback_kwargs)
  File "/home/haomao/Desktop/project/geowind_crawler/crawlermanage/views.py", line 585, in domain_autocomplete
    return HttpResponse(json.dump(ret))
TypeError: dump() takes at least 2 arguments (1 given)
2017-08-29 21:09:10,699 [Thread-6:140387300300544] [django.request:135] [ERROR]- Internal Server Error: /crawlermanage/domainautocomplete/
Traceback (most recent call last):
  File "/home/haomao/pythonVir/mainenv/local/lib/python2.7/site-packages/django/core/handlers/exception.py", line 41, in inner
    response = get_response(request)
  File "/home/haomao/pythonVir/mainenv/local/lib/python2.7/site-packages/django/core/handlers/base.py", line 249, in _legacy_get_response
    response = self._get_response(request)
  File "/home/haomao/pythonVir/mainenv/local/lib/python2.7/site-packages/django/core/handlers/base.py", line 187, in _get_response
    response = self.process_exception_by_middleware(e, request)
  File "/home/haomao/pythonVir/mainenv/local/lib/python2.7/site-packages/django/core/handlers/base.py", line 185, in _get_response
    response = wrapped_callback(request, *callback_args, **callback_kwargs)
  File "/home/haomao/Desktop/project/geowind_crawler/crawlermanage/views.py", line 585, in domain_autocomplete
    return HttpResponse(json.dump(ret))
TypeError: dump() takes at least 2 arguments (1 given)
2017-08-29 21:09:32,319 [Thread-3:139773692294912] [django.request:135] [ERROR]- Internal Server Error: /crawlermanage/domainautocomplete/
Traceback (most recent call last):
  File "/home/haomao/pythonVir/mainenv/local/lib/python2.7/site-packages/django/core/handlers/exception.py", line 41, in inner
    response = get_response(request)
  File "/home/haomao/pythonVir/mainenv/local/lib/python2.7/site-packages/django/core/handlers/base.py", line 249, in _legacy_get_response
    response = self._get_response(request)
  File "/home/haomao/pythonVir/mainenv/local/lib/python2.7/site-packages/django/core/handlers/base.py", line 187, in _get_response
    response = self.process_exception_by_middleware(e, request)
  File "/home/haomao/pythonVir/mainenv/local/lib/python2.7/site-packages/django/core/handlers/base.py", line 185, in _get_response
    response = wrapped_callback(request, *callback_args, **callback_kwargs)
  File "/home/haomao/Desktop/project/geowind_crawler/crawlermanage/views.py", line 585, in domain_autocomplete
    return HttpResponse(json.dump(ret))
TypeError: dump() takes at least 2 arguments (1 given)
2017-08-29 21:09:32,482 [Thread-4:139773692294912] [django.request:135] [ERROR]- Internal Server Error: /crawlermanage/domainautocomplete/
Traceback (most recent call last):
  File "/home/haomao/pythonVir/mainenv/local/lib/python2.7/site-packages/django/core/handlers/exception.py", line 41, in inner
    response = get_response(request)
  File "/home/haomao/pythonVir/mainenv/local/lib/python2.7/site-packages/django/core/handlers/base.py", line 249, in _legacy_get_response
    response = self._get_response(request)
  File "/home/haomao/pythonVir/mainenv/local/lib/python2.7/site-packages/django/core/handlers/base.py", line 187, in _get_response
    response = self.process_exception_by_middleware(e, request)
  File "/home/haomao/pythonVir/mainenv/local/lib/python2.7/site-packages/django/core/handlers/base.py", line 185, in _get_response
    response = wrapped_callback(request, *callback_args, **callback_kwargs)
  File "/home/haomao/Desktop/project/geowind_crawler/crawlermanage/views.py", line 585, in domain_autocomplete
    return HttpResponse(json.dump(ret))
TypeError: dump() takes at least 2 arguments (1 given)
2017-08-29 21:09:32,638 [Thread-5:139773692294912] [django.request:135] [ERROR]- Internal Server Error: /crawlermanage/domainautocomplete/
Traceback (most recent call last):
  File "/home/haomao/pythonVir/mainenv/local/lib/python2.7/site-packages/django/core/handlers/exception.py", line 41, in inner
    response = get_response(request)
  File "/home/haomao/pythonVir/mainenv/local/lib/python2.7/site-packages/django/core/handlers/base.py", line 249, in _legacy_get_response
    response = self._get_response(request)
  File "/home/haomao/pythonVir/mainenv/local/lib/python2.7/site-packages/django/core/handlers/base.py", line 187, in _get_response
    response = self.process_exception_by_middleware(e, request)
  File "/home/haomao/pythonVir/mainenv/local/lib/python2.7/site-packages/django/core/handlers/base.py", line 185, in _get_response
    response = wrapped_callback(request, *callback_args, **callback_kwargs)
  File "/home/haomao/Desktop/project/geowind_crawler/crawlermanage/views.py", line 585, in domain_autocomplete
    return HttpResponse(json.dump(ret))
TypeError: dump() takes at least 2 arguments (1 given)
2017-08-29 21:09:32,835 [Thread-6:139773692294912] [django.request:135] [ERROR]- Internal Server Error: /crawlermanage/domainautocomplete/
Traceback (most recent call last):
  File "/home/haomao/pythonVir/mainenv/local/lib/python2.7/site-packages/django/core/handlers/exception.py", line 41, in inner
    response = get_response(request)
  File "/home/haomao/pythonVir/mainenv/local/lib/python2.7/site-packages/django/core/handlers/base.py", line 249, in _legacy_get_response
    response = self._get_response(request)
  File "/home/haomao/pythonVir/mainenv/local/lib/python2.7/site-packages/django/core/handlers/base.py", line 187, in _get_response
    response = self.process_exception_by_middleware(e, request)
  File "/home/haomao/pythonVir/mainenv/local/lib/python2.7/site-packages/django/core/handlers/base.py", line 185, in _get_response
    response = wrapped_callback(request, *callback_args, **callback_kwargs)
  File "/home/haomao/Desktop/project/geowind_crawler/crawlermanage/views.py", line 585, in domain_autocomplete
    return HttpResponse(json.dump(ret))
TypeError: dump() takes at least 2 arguments (1 given)
2017-08-29 21:09:33,001 [Thread-7:139773692294912] [django.request:135] [ERROR]- Internal Server Error: /crawlermanage/domainautocomplete/
Traceback (most recent call last):
  File "/home/haomao/pythonVir/mainenv/local/lib/python2.7/site-packages/django/core/handlers/exception.py", line 41, in inner
    response = get_response(request)
  File "/home/haomao/pythonVir/mainenv/local/lib/python2.7/site-packages/django/core/handlers/base.py", line 249, in _legacy_get_response
    response = self._get_response(request)
  File "/home/haomao/pythonVir/mainenv/local/lib/python2.7/site-packages/django/core/handlers/base.py", line 187, in _get_response
    response = self.process_exception_by_middleware(e, request)
  File "/home/haomao/pythonVir/mainenv/local/lib/python2.7/site-packages/django/core/handlers/base.py", line 185, in _get_response
    response = wrapped_callback(request, *callback_args, **callback_kwargs)
  File "/home/haomao/Desktop/project/geowind_crawler/crawlermanage/views.py", line 585, in domain_autocomplete
    return HttpResponse(json.dump(ret))
TypeError: dump() takes at least 2 arguments (1 given)
2017-08-29 21:09:33,169 [Thread-8:139773692294912] [django.request:135] [ERROR]- Internal Server Error: /crawlermanage/domainautocomplete/
Traceback (most recent call last):
  File "/home/haomao/pythonVir/mainenv/local/lib/python2.7/site-packages/django/core/handlers/exception.py", line 41, in inner
    response = get_response(request)
  File "/home/haomao/pythonVir/mainenv/local/lib/python2.7/site-packages/django/core/handlers/base.py", line 249, in _legacy_get_response
    response = self._get_response(request)
  File "/home/haomao/pythonVir/mainenv/local/lib/python2.7/site-packages/django/core/handlers/base.py", line 187, in _get_response
    response = self.process_exception_by_middleware(e, request)
  File "/home/haomao/pythonVir/mainenv/local/lib/python2.7/site-packages/django/core/handlers/base.py", line 185, in _get_response
    response = wrapped_callback(request, *callback_args, **callback_kwargs)
  File "/home/haomao/Desktop/project/geowind_crawler/crawlermanage/views.py", line 585, in domain_autocomplete
    return HttpResponse(json.dump(ret))
TypeError: dump() takes at least 2 arguments (1 given)
2017-08-29 21:09:33,306 [Thread-9:139773692294912] [django.request:135] [ERROR]- Internal Server Error: /crawlermanage/domainautocomplete/
Traceback (most recent call last):
  File "/home/haomao/pythonVir/mainenv/local/lib/python2.7/site-packages/django/core/handlers/exception.py", line 41, in inner
    response = get_response(request)
  File "/home/haomao/pythonVir/mainenv/local/lib/python2.7/site-packages/django/core/handlers/base.py", line 249, in _legacy_get_response
    response = self._get_response(request)
  File "/home/haomao/pythonVir/mainenv/local/lib/python2.7/site-packages/django/core/handlers/base.py", line 187, in _get_response
    response = self.process_exception_by_middleware(e, request)
  File "/home/haomao/pythonVir/mainenv/local/lib/python2.7/site-packages/django/core/handlers/base.py", line 185, in _get_response
    response = wrapped_callback(request, *callback_args, **callback_kwargs)
  File "/home/haomao/Desktop/project/geowind_crawler/crawlermanage/views.py", line 585, in domain_autocomplete
    return HttpResponse(json.dump(ret))
TypeError: dump() takes at least 2 arguments (1 given)
2017-08-29 21:09:33,445 [Thread-10:139773692294912] [django.request:135] [ERROR]- Internal Server Error: /crawlermanage/domainautocomplete/
Traceback (most recent call last):
  File "/home/haomao/pythonVir/mainenv/local/lib/python2.7/site-packages/django/core/handlers/exception.py", line 41, in inner
    response = get_response(request)
  File "/home/haomao/pythonVir/mainenv/local/lib/python2.7/site-packages/django/core/handlers/base.py", line 249, in _legacy_get_response
    response = self._get_response(request)
  File "/home/haomao/pythonVir/mainenv/local/lib/python2.7/site-packages/django/core/handlers/base.py", line 187, in _get_response
    response = self.process_exception_by_middleware(e, request)
  File "/home/haomao/pythonVir/mainenv/local/lib/python2.7/site-packages/django/core/handlers/base.py", line 185, in _get_response
    response = wrapped_callback(request, *callback_args, **callback_kwargs)
  File "/home/haomao/Desktop/project/geowind_crawler/crawlermanage/views.py", line 585, in domain_autocomplete
    return HttpResponse(json.dump(ret))
TypeError: dump() takes at least 2 arguments (1 given)
2017-08-29 21:09:54,607 [Thread-4:140373665171200] [django.request:135] [ERROR]- Internal Server Error: /crawlermanage/domainautocomplete/
Traceback (most recent call last):
  File "/home/haomao/pythonVir/mainenv/local/lib/python2.7/site-packages/django/core/handlers/exception.py", line 41, in inner
    response = get_response(request)
  File "/home/haomao/pythonVir/mainenv/local/lib/python2.7/site-packages/django/core/handlers/base.py", line 249, in _legacy_get_response
    response = self._get_response(request)
  File "/home/haomao/pythonVir/mainenv/local/lib/python2.7/site-packages/django/core/handlers/base.py", line 187, in _get_response
    response = self.process_exception_by_middleware(e, request)
  File "/home/haomao/pythonVir/mainenv/local/lib/python2.7/site-packages/django/core/handlers/base.py", line 185, in _get_response
    response = wrapped_callback(request, *callback_args, **callback_kwargs)
  File "/home/haomao/Desktop/project/geowind_crawler/crawlermanage/views.py", line 581, in domain_autocomplete
    return HttpResponse(json.dump(ret))
TypeError: dump() takes at least 2 arguments (1 given)
2017-08-29 21:09:54,799 [Thread-5:140373665171200] [django.request:135] [ERROR]- Internal Server Error: /crawlermanage/domainautocomplete/
Traceback (most recent call last):
  File "/home/haomao/pythonVir/mainenv/local/lib/python2.7/site-packages/django/core/handlers/exception.py", line 41, in inner
    response = get_response(request)
  File "/home/haomao/pythonVir/mainenv/local/lib/python2.7/site-packages/django/core/handlers/base.py", line 249, in _legacy_get_response
    response = self._get_response(request)
  File "/home/haomao/pythonVir/mainenv/local/lib/python2.7/site-packages/django/core/handlers/base.py", line 187, in _get_response
    response = self.process_exception_by_middleware(e, request)
  File "/home/haomao/pythonVir/mainenv/local/lib/python2.7/site-packages/django/core/handlers/base.py", line 185, in _get_response
    response = wrapped_callback(request, *callback_args, **callback_kwargs)
  File "/home/haomao/Desktop/project/geowind_crawler/crawlermanage/views.py", line 581, in domain_autocomplete
    return HttpResponse(json.dump(ret))
TypeError: dump() takes at least 2 arguments (1 given)
2017-08-29 21:09:54,986 [Thread-6:140373665171200] [django.request:135] [ERROR]- Internal Server Error: /crawlermanage/domainautocomplete/
Traceback (most recent call last):
  File "/home/haomao/pythonVir/mainenv/local/lib/python2.7/site-packages/django/core/handlers/exception.py", line 41, in inner
    response = get_response(request)
  File "/home/haomao/pythonVir/mainenv/local/lib/python2.7/site-packages/django/core/handlers/base.py", line 249, in _legacy_get_response
    response = self._get_response(request)
  File "/home/haomao/pythonVir/mainenv/local/lib/python2.7/site-packages/django/core/handlers/base.py", line 187, in _get_response
    response = self.process_exception_by_middleware(e, request)
  File "/home/haomao/pythonVir/mainenv/local/lib/python2.7/site-packages/django/core/handlers/base.py", line 185, in _get_response
    response = wrapped_callback(request, *callback_args, **callback_kwargs)
  File "/home/haomao/Desktop/project/geowind_crawler/crawlermanage/views.py", line 581, in domain_autocomplete
    return HttpResponse(json.dump(ret))
TypeError: dump() takes at least 2 arguments (1 given)
2017-08-29 21:09:55,172 [Thread-7:140373665171200] [django.request:135] [ERROR]- Internal Server Error: /crawlermanage/domainautocomplete/
Traceback (most recent call last):
  File "/home/haomao/pythonVir/mainenv/local/lib/python2.7/site-packages/django/core/handlers/exception.py", line 41, in inner
    response = get_response(request)
  File "/home/haomao/pythonVir/mainenv/local/lib/python2.7/site-packages/django/core/handlers/base.py", line 249, in _legacy_get_response
    response = self._get_response(request)
  File "/home/haomao/pythonVir/mainenv/local/lib/python2.7/site-packages/django/core/handlers/base.py", line 187, in _get_response
    response = self.process_exception_by_middleware(e, request)
  File "/home/haomao/pythonVir/mainenv/local/lib/python2.7/site-packages/django/core/handlers/base.py", line 185, in _get_response
    response = wrapped_callback(request, *callback_args, **callback_kwargs)
  File "/home/haomao/Desktop/project/geowind_crawler/crawlermanage/views.py", line 581, in domain_autocomplete
    return HttpResponse(json.dump(ret))
TypeError: dump() takes at least 2 arguments (1 given)
2017-08-29 21:09:56,142 [Thread-8:140373665171200] [django.request:135] [ERROR]- Internal Server Error: /crawlermanage/domainautocomplete/
Traceback (most recent call last):
  File "/home/haomao/pythonVir/mainenv/local/lib/python2.7/site-packages/django/core/handlers/exception.py", line 41, in inner
    response = get_response(request)
  File "/home/haomao/pythonVir/mainenv/local/lib/python2.7/site-packages/django/core/handlers/base.py", line 249, in _legacy_get_response
    response = self._get_response(request)
  File "/home/haomao/pythonVir/mainenv/local/lib/python2.7/site-packages/django/core/handlers/base.py", line 187, in _get_response
    response = self.process_exception_by_middleware(e, request)
  File "/home/haomao/pythonVir/mainenv/local/lib/python2.7/site-packages/django/core/handlers/base.py", line 185, in _get_response
    response = wrapped_callback(request, *callback_args, **callback_kwargs)
  File "/home/haomao/Desktop/project/geowind_crawler/crawlermanage/views.py", line 581, in domain_autocomplete
    return HttpResponse(json.dump(ret))
TypeError: dump() takes at least 2 arguments (1 given)
2017-08-29 21:09:56,369 [Thread-9:140373665171200] [django.request:135] [ERROR]- Internal Server Error: /crawlermanage/domainautocomplete/
Traceback (most recent call last):
  File "/home/haomao/pythonVir/mainenv/local/lib/python2.7/site-packages/django/core/handlers/exception.py", line 41, in inner
    response = get_response(request)
  File "/home/haomao/pythonVir/mainenv/local/lib/python2.7/site-packages/django/core/handlers/base.py", line 249, in _legacy_get_response
    response = self._get_response(request)
  File "/home/haomao/pythonVir/mainenv/local/lib/python2.7/site-packages/django/core/handlers/base.py", line 187, in _get_response
    response = self.process_exception_by_middleware(e, request)
  File "/home/haomao/pythonVir/mainenv/local/lib/python2.7/site-packages/django/core/handlers/base.py", line 185, in _get_response
    response = wrapped_callback(request, *callback_args, **callback_kwargs)
  File "/home/haomao/Desktop/project/geowind_crawler/crawlermanage/views.py", line 581, in domain_autocomplete
    return HttpResponse(json.dump(ret))
TypeError: dump() takes at least 2 arguments (1 given)
2017-08-29 21:09:56,651 [Thread-10:140373665171200] [django.request:135] [ERROR]- Internal Server Error: /crawlermanage/domainautocomplete/
Traceback (most recent call last):
  File "/home/haomao/pythonVir/mainenv/local/lib/python2.7/site-packages/django/core/handlers/exception.py", line 41, in inner
    response = get_response(request)
  File "/home/haomao/pythonVir/mainenv/local/lib/python2.7/site-packages/django/core/handlers/base.py", line 249, in _legacy_get_response
    response = self._get_response(request)
  File "/home/haomao/pythonVir/mainenv/local/lib/python2.7/site-packages/django/core/handlers/base.py", line 187, in _get_response
    response = self.process_exception_by_middleware(e, request)
  File "/home/haomao/pythonVir/mainenv/local/lib/python2.7/site-packages/django/core/handlers/base.py", line 185, in _get_response
    response = wrapped_callback(request, *callback_args, **callback_kwargs)
  File "/home/haomao/Desktop/project/geowind_crawler/crawlermanage/views.py", line 581, in domain_autocomplete
    return HttpResponse(json.dump(ret))
TypeError: dump() takes at least 2 arguments (1 given)
2017-08-29 21:09:57,551 [Thread-11:140373665171200] [django.request:135] [ERROR]- Internal Server Error: /crawlermanage/domainautocomplete/
Traceback (most recent call last):
  File "/home/haomao/pythonVir/mainenv/local/lib/python2.7/site-packages/django/core/handlers/exception.py", line 41, in inner
    response = get_response(request)
  File "/home/haomao/pythonVir/mainenv/local/lib/python2.7/site-packages/django/core/handlers/base.py", line 249, in _legacy_get_response
    response = self._get_response(request)
  File "/home/haomao/pythonVir/mainenv/local/lib/python2.7/site-packages/django/core/handlers/base.py", line 187, in _get_response
    response = self.process_exception_by_middleware(e, request)
  File "/home/haomao/pythonVir/mainenv/local/lib/python2.7/site-packages/django/core/handlers/base.py", line 185, in _get_response
    response = wrapped_callback(request, *callback_args, **callback_kwargs)
  File "/home/haomao/Desktop/project/geowind_crawler/crawlermanage/views.py", line 581, in domain_autocomplete
    return HttpResponse(json.dump(ret))
TypeError: dump() takes at least 2 arguments (1 given)
2017-08-29 21:09:57,904 [Thread-12:140373665171200] [django.request:135] [ERROR]- Internal Server Error: /crawlermanage/domainautocomplete/
Traceback (most recent call last):
  File "/home/haomao/pythonVir/mainenv/local/lib/python2.7/site-packages/django/core/handlers/exception.py", line 41, in inner
    response = get_response(request)
  File "/home/haomao/pythonVir/mainenv/local/lib/python2.7/site-packages/django/core/handlers/base.py", line 249, in _legacy_get_response
    response = self._get_response(request)
  File "/home/haomao/pythonVir/mainenv/local/lib/python2.7/site-packages/django/core/handlers/base.py", line 187, in _get_response
    response = self.process_exception_by_middleware(e, request)
  File "/home/haomao/pythonVir/mainenv/local/lib/python2.7/site-packages/django/core/handlers/base.py", line 185, in _get_response
    response = wrapped_callback(request, *callback_args, **callback_kwargs)
  File "/home/haomao/Desktop/project/geowind_crawler/crawlermanage/views.py", line 581, in domain_autocomplete
    return HttpResponse(json.dump(ret))
TypeError: dump() takes at least 2 arguments (1 given)
2017-08-29 21:09:58,424 [Thread-13:140373665171200] [django.request:135] [ERROR]- Internal Server Error: /crawlermanage/domainautocomplete/
Traceback (most recent call last):
  File "/home/haomao/pythonVir/mainenv/local/lib/python2.7/site-packages/django/core/handlers/exception.py", line 41, in inner
    response = get_response(request)
  File "/home/haomao/pythonVir/mainenv/local/lib/python2.7/site-packages/django/core/handlers/base.py", line 249, in _legacy_get_response
    response = self._get_response(request)
  File "/home/haomao/pythonVir/mainenv/local/lib/python2.7/site-packages/django/core/handlers/base.py", line 187, in _get_response
    response = self.process_exception_by_middleware(e, request)
  File "/home/haomao/pythonVir/mainenv/local/lib/python2.7/site-packages/django/core/handlers/base.py", line 185, in _get_response
    response = wrapped_callback(request, *callback_args, **callback_kwargs)
  File "/home/haomao/Desktop/project/geowind_crawler/crawlermanage/views.py", line 581, in domain_autocomplete
    return HttpResponse(json.dump(ret))
TypeError: dump() takes at least 2 arguments (1 given)
2017-08-29 21:09:58,643 [Thread-14:140373665171200] [django.request:135] [ERROR]- Internal Server Error: /crawlermanage/domainautocomplete/
Traceback (most recent call last):
  File "/home/haomao/pythonVir/mainenv/local/lib/python2.7/site-packages/django/core/handlers/exception.py", line 41, in inner
    response = get_response(request)
  File "/home/haomao/pythonVir/mainenv/local/lib/python2.7/site-packages/django/core/handlers/base.py", line 249, in _legacy_get_response
    response = self._get_response(request)
  File "/home/haomao/pythonVir/mainenv/local/lib/python2.7/site-packages/django/core/handlers/base.py", line 187, in _get_response
    response = self.process_exception_by_middleware(e, request)
  File "/home/haomao/pythonVir/mainenv/local/lib/python2.7/site-packages/django/core/handlers/base.py", line 185, in _get_response
    response = wrapped_callback(request, *callback_args, **callback_kwargs)
  File "/home/haomao/Desktop/project/geowind_crawler/crawlermanage/views.py", line 581, in domain_autocomplete
    return HttpResponse(json.dump(ret))
TypeError: dump() takes at least 2 arguments (1 given)
2017-08-29 21:09:59,094 [Thread-15:140373665171200] [django.request:135] [ERROR]- Internal Server Error: /crawlermanage/domainautocomplete/
Traceback (most recent call last):
  File "/home/haomao/pythonVir/mainenv/local/lib/python2.7/site-packages/django/core/handlers/exception.py", line 41, in inner
    response = get_response(request)
  File "/home/haomao/pythonVir/mainenv/local/lib/python2.7/site-packages/django/core/handlers/base.py", line 249, in _legacy_get_response
    response = self._get_response(request)
  File "/home/haomao/pythonVir/mainenv/local/lib/python2.7/site-packages/django/core/handlers/base.py", line 187, in _get_response
    response = self.process_exception_by_middleware(e, request)
  File "/home/haomao/pythonVir/mainenv/local/lib/python2.7/site-packages/django/core/handlers/base.py", line 185, in _get_response
    response = wrapped_callback(request, *callback_args, **callback_kwargs)
  File "/home/haomao/Desktop/project/geowind_crawler/crawlermanage/views.py", line 581, in domain_autocomplete
    return HttpResponse(json.dump(ret))
TypeError: dump() takes at least 2 arguments (1 given)
2017-08-29 21:09:59,318 [Thread-16:140373665171200] [django.request:135] [ERROR]- Internal Server Error: /crawlermanage/domainautocomplete/
Traceback (most recent call last):
  File "/home/haomao/pythonVir/mainenv/local/lib/python2.7/site-packages/django/core/handlers/exception.py", line 41, in inner
    response = get_response(request)
  File "/home/haomao/pythonVir/mainenv/local/lib/python2.7/site-packages/django/core/handlers/base.py", line 249, in _legacy_get_response
    response = self._get_response(request)
  File "/home/haomao/pythonVir/mainenv/local/lib/python2.7/site-packages/django/core/handlers/base.py", line 187, in _get_response
    response = self.process_exception_by_middleware(e, request)
  File "/home/haomao/pythonVir/mainenv/local/lib/python2.7/site-packages/django/core/handlers/base.py", line 185, in _get_response
    response = wrapped_callback(request, *callback_args, **callback_kwargs)
  File "/home/haomao/Desktop/project/geowind_crawler/crawlermanage/views.py", line 581, in domain_autocomplete
    return HttpResponse(json.dump(ret))
TypeError: dump() takes at least 2 arguments (1 given)
2017-08-29 21:22:36,286 [Thread-17:140373665171200] [django.request:135] [ERROR]- Internal Server Error: /crawlermanage/domainautocomplete/
Traceback (most recent call last):
  File "/home/haomao/pythonVir/mainenv/local/lib/python2.7/site-packages/django/core/handlers/exception.py", line 41, in inner
    response = get_response(request)
  File "/home/haomao/pythonVir/mainenv/local/lib/python2.7/site-packages/django/core/handlers/base.py", line 249, in _legacy_get_response
    response = self._get_response(request)
  File "/home/haomao/pythonVir/mainenv/local/lib/python2.7/site-packages/django/core/handlers/base.py", line 187, in _get_response
    response = self.process_exception_by_middleware(e, request)
  File "/home/haomao/pythonVir/mainenv/local/lib/python2.7/site-packages/django/core/handlers/base.py", line 185, in _get_response
    response = wrapped_callback(request, *callback_args, **callback_kwargs)
  File "/home/haomao/Desktop/project/geowind_crawler/crawlermanage/views.py", line 581, in domain_autocomplete
    return HttpResponse(json.dump(ret))
TypeError: dump() takes at least 2 arguments (1 given)
2017-08-29 21:24:33,104 [Thread-3:140326899439360] [django.request:135] [ERROR]- Internal Server Error: /crawlermanage/domainautocomplete/
Traceback (most recent call last):
  File "/home/haomao/pythonVir/mainenv/local/lib/python2.7/site-packages/django/core/handlers/exception.py", line 41, in inner
    response = get_response(request)
  File "/home/haomao/pythonVir/mainenv/local/lib/python2.7/site-packages/django/core/handlers/base.py", line 249, in _legacy_get_response
    response = self._get_response(request)
  File "/home/haomao/pythonVir/mainenv/local/lib/python2.7/site-packages/django/core/handlers/base.py", line 187, in _get_response
    response = self.process_exception_by_middleware(e, request)
  File "/home/haomao/pythonVir/mainenv/local/lib/python2.7/site-packages/django/core/handlers/base.py", line 185, in _get_response
    response = wrapped_callback(request, *callback_args, **callback_kwargs)
  File "/home/haomao/Desktop/project/geowind_crawler/crawlermanage/views.py", line 581, in domain_autocomplete
    return HttpResponse({'abc',['a','b','c']},mimetype='application/json')
TypeError: unhashable type: 'list'
2017-08-29 21:24:33,921 [Thread-4:140326891046656] [django.request:135] [ERROR]- Internal Server Error: /crawlermanage/domainautocomplete/
Traceback (most recent call last):
  File "/home/haomao/pythonVir/mainenv/local/lib/python2.7/site-packages/django/core/handlers/exception.py", line 41, in inner
    response = get_response(request)
  File "/home/haomao/pythonVir/mainenv/local/lib/python2.7/site-packages/django/core/handlers/base.py", line 249, in _legacy_get_response
    response = self._get_response(request)
  File "/home/haomao/pythonVir/mainenv/local/lib/python2.7/site-packages/django/core/handlers/base.py", line 187, in _get_response
    response = self.process_exception_by_middleware(e, request)
  File "/home/haomao/pythonVir/mainenv/local/lib/python2.7/site-packages/django/core/handlers/base.py", line 185, in _get_response
    response = wrapped_callback(request, *callback_args, **callback_kwargs)
  File "/home/haomao/Desktop/project/geowind_crawler/crawlermanage/views.py", line 581, in domain_autocomplete
    return HttpResponse({'abc',['a','b','c']},mimetype='application/json')
TypeError: unhashable type: 'list'
2017-08-29 21:24:34,125 [Thread-5:140326882653952] [django.request:135] [ERROR]- Internal Server Error: /crawlermanage/domainautocomplete/
Traceback (most recent call last):
  File "/home/haomao/pythonVir/mainenv/local/lib/python2.7/site-packages/django/core/handlers/exception.py", line 41, in inner
    response = get_response(request)
  File "/home/haomao/pythonVir/mainenv/local/lib/python2.7/site-packages/django/core/handlers/base.py", line 249, in _legacy_get_response
    response = self._get_response(request)
  File "/home/haomao/pythonVir/mainenv/local/lib/python2.7/site-packages/django/core/handlers/base.py", line 187, in _get_response
    response = self.process_exception_by_middleware(e, request)
  File "/home/haomao/pythonVir/mainenv/local/lib/python2.7/site-packages/django/core/handlers/base.py", line 185, in _get_response
    response = wrapped_callback(request, *callback_args, **callback_kwargs)
  File "/home/haomao/Desktop/project/geowind_crawler/crawlermanage/views.py", line 581, in domain_autocomplete
    return HttpResponse({'abc',['a','b','c']},mimetype='application/json')
TypeError: unhashable type: 'list'
2017-08-29 21:24:34,286 [Thread-6:140326874261248] [django.request:135] [ERROR]- Internal Server Error: /crawlermanage/domainautocomplete/
Traceback (most recent call last):
  File "/home/haomao/pythonVir/mainenv/local/lib/python2.7/site-packages/django/core/handlers/exception.py", line 41, in inner
    response = get_response(request)
  File "/home/haomao/pythonVir/mainenv/local/lib/python2.7/site-packages/django/core/handlers/base.py", line 249, in _legacy_get_response
    response = self._get_response(request)
  File "/home/haomao/pythonVir/mainenv/local/lib/python2.7/site-packages/django/core/handlers/base.py", line 187, in _get_response
    response = self.process_exception_by_middleware(e, request)
  File "/home/haomao/pythonVir/mainenv/local/lib/python2.7/site-packages/django/core/handlers/base.py", line 185, in _get_response
    response = wrapped_callback(request, *callback_args, **callback_kwargs)
  File "/home/haomao/Desktop/project/geowind_crawler/crawlermanage/views.py", line 581, in domain_autocomplete
    return HttpResponse({'abc',['a','b','c']},mimetype='application/json')
TypeError: unhashable type: 'list'
2017-08-29 21:24:34,446 [Thread-7:140326865868544] [django.request:135] [ERROR]- Internal Server Error: /crawlermanage/domainautocomplete/
Traceback (most recent call last):
  File "/home/haomao/pythonVir/mainenv/local/lib/python2.7/site-packages/django/core/handlers/exception.py", line 41, in inner
    response = get_response(request)
  File "/home/haomao/pythonVir/mainenv/local/lib/python2.7/site-packages/django/core/handlers/base.py", line 249, in _legacy_get_response
    response = self._get_response(request)
  File "/home/haomao/pythonVir/mainenv/local/lib/python2.7/site-packages/django/core/handlers/base.py", line 187, in _get_response
    response = self.process_exception_by_middleware(e, request)
  File "/home/haomao/pythonVir/mainenv/local/lib/python2.7/site-packages/django/core/handlers/base.py", line 185, in _get_response
    response = wrapped_callback(request, *callback_args, **callback_kwargs)
  File "/home/haomao/Desktop/project/geowind_crawler/crawlermanage/views.py", line 581, in domain_autocomplete
    return HttpResponse({'abc',['a','b','c']},mimetype='application/json')
TypeError: unhashable type: 'list'
2017-08-29 21:24:34,598 [Thread-8:140326865868544] [django.request:135] [ERROR]- Internal Server Error: /crawlermanage/domainautocomplete/
Traceback (most recent call last):
  File "/home/haomao/pythonVir/mainenv/local/lib/python2.7/site-packages/django/core/handlers/exception.py", line 41, in inner
    response = get_response(request)
  File "/home/haomao/pythonVir/mainenv/local/lib/python2.7/site-packages/django/core/handlers/base.py", line 249, in _legacy_get_response
    response = self._get_response(request)
  File "/home/haomao/pythonVir/mainenv/local/lib/python2.7/site-packages/django/core/handlers/base.py", line 187, in _get_response
    response = self.process_exception_by_middleware(e, request)
  File "/home/haomao/pythonVir/mainenv/local/lib/python2.7/site-packages/django/core/handlers/base.py", line 185, in _get_response
    response = wrapped_callback(request, *callback_args, **callback_kwargs)
  File "/home/haomao/Desktop/project/geowind_crawler/crawlermanage/views.py", line 581, in domain_autocomplete
    return HttpResponse({'abc',['a','b','c']},mimetype='application/json')
TypeError: unhashable type: 'list'
2017-08-29 21:24:34,733 [Thread-9:140326865868544] [django.request:135] [ERROR]- Internal Server Error: /crawlermanage/domainautocomplete/
Traceback (most recent call last):
  File "/home/haomao/pythonVir/mainenv/local/lib/python2.7/site-packages/django/core/handlers/exception.py", line 41, in inner
    response = get_response(request)
  File "/home/haomao/pythonVir/mainenv/local/lib/python2.7/site-packages/django/core/handlers/base.py", line 249, in _legacy_get_response
    response = self._get_response(request)
  File "/home/haomao/pythonVir/mainenv/local/lib/python2.7/site-packages/django/core/handlers/base.py", line 187, in _get_response
    response = self.process_exception_by_middleware(e, request)
  File "/home/haomao/pythonVir/mainenv/local/lib/python2.7/site-packages/django/core/handlers/base.py", line 185, in _get_response
    response = wrapped_callback(request, *callback_args, **callback_kwargs)
  File "/home/haomao/Desktop/project/geowind_crawler/crawlermanage/views.py", line 581, in domain_autocomplete
    return HttpResponse({'abc',['a','b','c']},mimetype='application/json')
TypeError: unhashable type: 'list'
2017-08-29 21:25:37,736 [Thread-3:140375830292224] [django.request:135] [ERROR]- Internal Server Error: /crawlermanage/domainautocomplete/
Traceback (most recent call last):
  File "/home/haomao/pythonVir/mainenv/local/lib/python2.7/site-packages/django/core/handlers/exception.py", line 41, in inner
    response = get_response(request)
  File "/home/haomao/pythonVir/mainenv/local/lib/python2.7/site-packages/django/core/handlers/base.py", line 249, in _legacy_get_response
    response = self._get_response(request)
  File "/home/haomao/pythonVir/mainenv/local/lib/python2.7/site-packages/django/core/handlers/base.py", line 187, in _get_response
    response = self.process_exception_by_middleware(e, request)
  File "/home/haomao/pythonVir/mainenv/local/lib/python2.7/site-packages/django/core/handlers/base.py", line 185, in _get_response
    response = wrapped_callback(request, *callback_args, **callback_kwargs)
  File "/home/haomao/Desktop/project/geowind_crawler/crawlermanage/views.py", line 585, in domain_autocomplete
    return HttpResponse(json_resp,mimetype='application/json')
  File "/home/haomao/pythonVir/mainenv/local/lib/python2.7/site-packages/django/http/response.py", line 301, in __init__
    super(HttpResponse, self).__init__(*args, **kwargs)
TypeError: __init__() got an unexpected keyword argument 'mimetype'
2017-08-29 21:25:38,633 [Thread-4:140375821899520] [django.request:135] [ERROR]- Internal Server Error: /crawlermanage/domainautocomplete/
Traceback (most recent call last):
  File "/home/haomao/pythonVir/mainenv/local/lib/python2.7/site-packages/django/core/handlers/exception.py", line 41, in inner
    response = get_response(request)
  File "/home/haomao/pythonVir/mainenv/local/lib/python2.7/site-packages/django/core/handlers/base.py", line 249, in _legacy_get_response
    response = self._get_response(request)
  File "/home/haomao/pythonVir/mainenv/local/lib/python2.7/site-packages/django/core/handlers/base.py", line 187, in _get_response
    response = self.process_exception_by_middleware(e, request)
  File "/home/haomao/pythonVir/mainenv/local/lib/python2.7/site-packages/django/core/handlers/base.py", line 185, in _get_response
    response = wrapped_callback(request, *callback_args, **callback_kwargs)
  File "/home/haomao/Desktop/project/geowind_crawler/crawlermanage/views.py", line 585, in domain_autocomplete
    return HttpResponse(json_resp,mimetype='application/json')
  File "/home/haomao/pythonVir/mainenv/local/lib/python2.7/site-packages/django/http/response.py", line 301, in __init__
    super(HttpResponse, self).__init__(*args, **kwargs)
TypeError: __init__() got an unexpected keyword argument 'mimetype'
2017-08-29 21:25:38,827 [Thread-5:140375813506816] [django.request:135] [ERROR]- Internal Server Error: /crawlermanage/domainautocomplete/
Traceback (most recent call last):
  File "/home/haomao/pythonVir/mainenv/local/lib/python2.7/site-packages/django/core/handlers/exception.py", line 41, in inner
    response = get_response(request)
  File "/home/haomao/pythonVir/mainenv/local/lib/python2.7/site-packages/django/core/handlers/base.py", line 249, in _legacy_get_response
    response = self._get_response(request)
  File "/home/haomao/pythonVir/mainenv/local/lib/python2.7/site-packages/django/core/handlers/base.py", line 187, in _get_response
    response = self.process_exception_by_middleware(e, request)
  File "/home/haomao/pythonVir/mainenv/local/lib/python2.7/site-packages/django/core/handlers/base.py", line 185, in _get_response
    response = wrapped_callback(request, *callback_args, **callback_kwargs)
  File "/home/haomao/Desktop/project/geowind_crawler/crawlermanage/views.py", line 585, in domain_autocomplete
    return HttpResponse(json_resp,mimetype='application/json')
  File "/home/haomao/pythonVir/mainenv/local/lib/python2.7/site-packages/django/http/response.py", line 301, in __init__
    super(HttpResponse, self).__init__(*args, **kwargs)
TypeError: __init__() got an unexpected keyword argument 'mimetype'
2017-08-29 21:25:39,005 [Thread-6:140375805114112] [django.request:135] [ERROR]- Internal Server Error: /crawlermanage/domainautocomplete/
Traceback (most recent call last):
  File "/home/haomao/pythonVir/mainenv/local/lib/python2.7/site-packages/django/core/handlers/exception.py", line 41, in inner
    response = get_response(request)
  File "/home/haomao/pythonVir/mainenv/local/lib/python2.7/site-packages/django/core/handlers/base.py", line 249, in _legacy_get_response
    response = self._get_response(request)
  File "/home/haomao/pythonVir/mainenv/local/lib/python2.7/site-packages/django/core/handlers/base.py", line 187, in _get_response
    response = self.process_exception_by_middleware(e, request)
  File "/home/haomao/pythonVir/mainenv/local/lib/python2.7/site-packages/django/core/handlers/base.py", line 185, in _get_response
    response = wrapped_callback(request, *callback_args, **callback_kwargs)
  File "/home/haomao/Desktop/project/geowind_crawler/crawlermanage/views.py", line 585, in domain_autocomplete
    return HttpResponse(json_resp,mimetype='application/json')
  File "/home/haomao/pythonVir/mainenv/local/lib/python2.7/site-packages/django/http/response.py", line 301, in __init__
    super(HttpResponse, self).__init__(*args, **kwargs)
TypeError: __init__() got an unexpected keyword argument 'mimetype'
2017-08-29 21:25:39,212 [Thread-7:140375796721408] [django.request:135] [ERROR]- Internal Server Error: /crawlermanage/domainautocomplete/
Traceback (most recent call last):
  File "/home/haomao/pythonVir/mainenv/local/lib/python2.7/site-packages/django/core/handlers/exception.py", line 41, in inner
    response = get_response(request)
  File "/home/haomao/pythonVir/mainenv/local/lib/python2.7/site-packages/django/core/handlers/base.py", line 249, in _legacy_get_response
    response = self._get_response(request)
  File "/home/haomao/pythonVir/mainenv/local/lib/python2.7/site-packages/django/core/handlers/base.py", line 187, in _get_response
    response = self.process_exception_by_middleware(e, request)
  File "/home/haomao/pythonVir/mainenv/local/lib/python2.7/site-packages/django/core/handlers/base.py", line 185, in _get_response
    response = wrapped_callback(request, *callback_args, **callback_kwargs)
  File "/home/haomao/Desktop/project/geowind_crawler/crawlermanage/views.py", line 585, in domain_autocomplete
    return HttpResponse(json_resp,mimetype='application/json')
  File "/home/haomao/pythonVir/mainenv/local/lib/python2.7/site-packages/django/http/response.py", line 301, in __init__
    super(HttpResponse, self).__init__(*args, **kwargs)
TypeError: __init__() got an unexpected keyword argument 'mimetype'
2017-08-29 21:25:39,447 [Thread-8:140375796721408] [django.request:135] [ERROR]- Internal Server Error: /crawlermanage/domainautocomplete/
Traceback (most recent call last):
  File "/home/haomao/pythonVir/mainenv/local/lib/python2.7/site-packages/django/core/handlers/exception.py", line 41, in inner
    response = get_response(request)
  File "/home/haomao/pythonVir/mainenv/local/lib/python2.7/site-packages/django/core/handlers/base.py", line 249, in _legacy_get_response
    response = self._get_response(request)
  File "/home/haomao/pythonVir/mainenv/local/lib/python2.7/site-packages/django/core/handlers/base.py", line 187, in _get_response
    response = self.process_exception_by_middleware(e, request)
  File "/home/haomao/pythonVir/mainenv/local/lib/python2.7/site-packages/django/core/handlers/base.py", line 185, in _get_response
    response = wrapped_callback(request, *callback_args, **callback_kwargs)
  File "/home/haomao/Desktop/project/geowind_crawler/crawlermanage/views.py", line 585, in domain_autocomplete
    return HttpResponse(json_resp,mimetype='application/json')
  File "/home/haomao/pythonVir/mainenv/local/lib/python2.7/site-packages/django/http/response.py", line 301, in __init__
    super(HttpResponse, self).__init__(*args, **kwargs)
TypeError: __init__() got an unexpected keyword argument 'mimetype'
2017-08-29 21:36:58,901 [Thread-10:140375796721408] [django.request:152] [WARNING]- Not Found: /crawlermanage/layouty/
2017-08-30 18:07:32,392 [Thread-3:139816452339456] [django.request:152] [WARNING]- Not Found: /favicon.ico
2017-08-30 20:52:59,025 [Thread-12:139816217868032] [django.request:135] [ERROR]- Internal Server Error: /crawlermanage/settings/
Traceback (most recent call last):
  File "/home/haomao/pythonVir/mainenv/local/lib/python2.7/site-packages/django/core/handlers/exception.py", line 41, in inner
    response = get_response(request)
  File "/home/haomao/pythonVir/mainenv/local/lib/python2.7/site-packages/django/core/handlers/base.py", line 249, in _legacy_get_response
    response = self._get_response(request)
  File "/home/haomao/pythonVir/mainenv/local/lib/python2.7/site-packages/django/core/handlers/base.py", line 198, in _get_response
    "returned None instead." % (callback.__module__, view_name)
ValueError: The view crawlermanage.views.settings didn't return an HttpResponse object. It returned None instead.
2017-08-30 20:52:59,242 [Thread-13:139816217868032] [django.request:152] [WARNING]- Not Found: /favicon.ico
2017-08-30 20:53:00,130 [Thread-14:139816217868032] [django.request:135] [ERROR]- Internal Server Error: /crawlermanage/settings/
Traceback (most recent call last):
  File "/home/haomao/pythonVir/mainenv/local/lib/python2.7/site-packages/django/core/handlers/exception.py", line 41, in inner
    response = get_response(request)
  File "/home/haomao/pythonVir/mainenv/local/lib/python2.7/site-packages/django/core/handlers/base.py", line 249, in _legacy_get_response
    response = self._get_response(request)
  File "/home/haomao/pythonVir/mainenv/local/lib/python2.7/site-packages/django/core/handlers/base.py", line 198, in _get_response
    "returned None instead." % (callback.__module__, view_name)
ValueError: The view crawlermanage.views.settings didn't return an HttpResponse object. It returned None instead.
2017-08-30 21:01:49,128 [Thread-15:139816217868032] [django.request:135] [ERROR]- Internal Server Error: /crawlermanage/settings/
Traceback (most recent call last):
  File "/home/haomao/pythonVir/mainenv/local/lib/python2.7/site-packages/django/core/handlers/exception.py", line 41, in inner
    response = get_response(request)
  File "/home/haomao/pythonVir/mainenv/local/lib/python2.7/site-packages/django/core/handlers/base.py", line 249, in _legacy_get_response
    response = self._get_response(request)
  File "/home/haomao/pythonVir/mainenv/local/lib/python2.7/site-packages/django/core/handlers/base.py", line 198, in _get_response
    "returned None instead." % (callback.__module__, view_name)
ValueError: The view crawlermanage.views.settings didn't return an HttpResponse object. It returned None instead.
2017-08-30 21:02:14,343 [Thread-16:139816217868032] [django.request:135] [ERROR]- Internal Server Error: /crawlermanage/settings/
Traceback (most recent call last):
  File "/home/haomao/pythonVir/mainenv/local/lib/python2.7/site-packages/django/core/handlers/exception.py", line 41, in inner
    response = get_response(request)
  File "/home/haomao/pythonVir/mainenv/local/lib/python2.7/site-packages/django/core/handlers/base.py", line 249, in _legacy_get_response
    response = self._get_response(request)
  File "/home/haomao/pythonVir/mainenv/local/lib/python2.7/site-packages/django/core/handlers/base.py", line 198, in _get_response
    "returned None instead." % (callback.__module__, view_name)
ValueError: The view crawlermanage.views.settings didn't return an HttpResponse object. It returned None instead.
2017-08-30 21:03:03,192 [Thread-17:139816217868032] [django.request:135] [ERROR]- Internal Server Error: /crawlermanage/settings/
Traceback (most recent call last):
  File "/home/haomao/pythonVir/mainenv/local/lib/python2.7/site-packages/django/core/handlers/exception.py", line 41, in inner
    response = get_response(request)
  File "/home/haomao/pythonVir/mainenv/local/lib/python2.7/site-packages/django/core/handlers/base.py", line 249, in _legacy_get_response
    response = self._get_response(request)
  File "/home/haomao/pythonVir/mainenv/local/lib/python2.7/site-packages/django/core/handlers/base.py", line 198, in _get_response
    "returned None instead." % (callback.__module__, view_name)
ValueError: The view crawlermanage.views.settings didn't return an HttpResponse object. It returned None instead.
2017-08-30 21:07:13,155 [Thread-18:139816217868032] [django.request:135] [ERROR]- Internal Server Error: /crawlermanage/settings/
Traceback (most recent call last):
  File "/home/haomao/pythonVir/mainenv/local/lib/python2.7/site-packages/django/core/handlers/exception.py", line 41, in inner
    response = get_response(request)
  File "/home/haomao/pythonVir/mainenv/local/lib/python2.7/site-packages/django/core/handlers/base.py", line 249, in _legacy_get_response
    response = self._get_response(request)
  File "/home/haomao/pythonVir/mainenv/local/lib/python2.7/site-packages/django/core/handlers/base.py", line 198, in _get_response
    "returned None instead." % (callback.__module__, view_name)
ValueError: The view crawlermanage.views.settings didn't return an HttpResponse object. It returned None instead.
2017-08-30 21:08:05,741 [Thread-19:139816217868032] [django.request:135] [ERROR]- Internal Server Error: /crawlermanage/settings/
Traceback (most recent call last):
  File "/home/haomao/pythonVir/mainenv/local/lib/python2.7/site-packages/django/core/handlers/exception.py", line 41, in inner
    response = get_response(request)
  File "/home/haomao/pythonVir/mainenv/local/lib/python2.7/site-packages/django/core/handlers/base.py", line 249, in _legacy_get_response
    response = self._get_response(request)
  File "/home/haomao/pythonVir/mainenv/local/lib/python2.7/site-packages/django/core/handlers/base.py", line 198, in _get_response
    "returned None instead." % (callback.__module__, view_name)
ValueError: The view crawlermanage.views.settings didn't return an HttpResponse object. It returned None instead.
2017-08-30 21:08:24,869 [Thread-20:139816217868032] [django.request:135] [ERROR]- Internal Server Error: /crawlermanage/settings/
Traceback (most recent call last):
  File "/home/haomao/pythonVir/mainenv/local/lib/python2.7/site-packages/django/core/handlers/exception.py", line 41, in inner
    response = get_response(request)
  File "/home/haomao/pythonVir/mainenv/local/lib/python2.7/site-packages/django/core/handlers/base.py", line 249, in _legacy_get_response
    response = self._get_response(request)
  File "/home/haomao/pythonVir/mainenv/local/lib/python2.7/site-packages/django/core/handlers/base.py", line 198, in _get_response
    "returned None instead." % (callback.__module__, view_name)
ValueError: The view crawlermanage.views.settings didn't return an HttpResponse object. It returned None instead.
2017-08-30 21:11:06,443 [Thread-21:139816217868032] [django.request:135] [ERROR]- Internal Server Error: /crawlermanage/settings/
Traceback (most recent call last):
  File "/home/haomao/pythonVir/mainenv/local/lib/python2.7/site-packages/django/core/handlers/exception.py", line 41, in inner
    response = get_response(request)
  File "/home/haomao/pythonVir/mainenv/local/lib/python2.7/site-packages/django/core/handlers/base.py", line 249, in _legacy_get_response
    response = self._get_response(request)
  File "/home/haomao/pythonVir/mainenv/local/lib/python2.7/site-packages/django/core/handlers/base.py", line 198, in _get_response
    "returned None instead." % (callback.__module__, view_name)
ValueError: The view crawlermanage.views.settings didn't return an HttpResponse object. It returned None instead.
2017-08-30 21:12:43,861 [Thread-22:139816217868032] [django.request:152] [WARNING]- Not Found: /crawlermanage/dubug
2017-08-30 21:23:10,625 [Thread-42:139816435554048] [django.request:135] [ERROR]- Internal Server Error: /crawlermanage/settings/
Traceback (most recent call last):
  File "/home/haomao/pythonVir/mainenv/local/lib/python2.7/site-packages/django/core/handlers/exception.py", line 41, in inner
    response = get_response(request)
  File "/home/haomao/pythonVir/mainenv/local/lib/python2.7/site-packages/django/core/handlers/base.py", line 249, in _legacy_get_response
    response = self._get_response(request)
  File "/home/haomao/pythonVir/mainenv/local/lib/python2.7/site-packages/django/core/handlers/base.py", line 198, in _get_response
    "returned None instead." % (callback.__module__, view_name)
ValueError: The view crawlermanage.views.settings didn't return an HttpResponse object. It returned None instead.
2017-08-30 21:23:11,455 [Thread-43:139816435554048] [django.request:135] [ERROR]- Internal Server Error: /crawlermanage/settings/
Traceback (most recent call last):
  File "/home/haomao/pythonVir/mainenv/local/lib/python2.7/site-packages/django/core/handlers/exception.py", line 41, in inner
    response = get_response(request)
  File "/home/haomao/pythonVir/mainenv/local/lib/python2.7/site-packages/django/core/handlers/base.py", line 249, in _legacy_get_response
    response = self._get_response(request)
  File "/home/haomao/pythonVir/mainenv/local/lib/python2.7/site-packages/django/core/handlers/base.py", line 198, in _get_response
    "returned None instead." % (callback.__module__, view_name)
ValueError: The view crawlermanage.views.settings didn't return an HttpResponse object. It returned None instead.
2017-08-30 21:27:38,232 [Thread-44:139816435554048] [django.request:135] [ERROR]- Internal Server Error: /crawlermanage/settings/
Traceback (most recent call last):
  File "/home/haomao/pythonVir/mainenv/local/lib/python2.7/site-packages/django/core/handlers/exception.py", line 41, in inner
    response = get_response(request)
  File "/home/haomao/pythonVir/mainenv/local/lib/python2.7/site-packages/django/core/handlers/base.py", line 249, in _legacy_get_response
    response = self._get_response(request)
  File "/home/haomao/pythonVir/mainenv/local/lib/python2.7/site-packages/django/core/handlers/base.py", line 198, in _get_response
    "returned None instead." % (callback.__module__, view_name)
ValueError: The view crawlermanage.views.settings didn't return an HttpResponse object. It returned None instead.
2017-08-30 21:28:19,196 [Thread-45:139816435554048] [django.request:135] [ERROR]- Internal Server Error: /crawlermanage/settings/
Traceback (most recent call last):
  File "/home/haomao/pythonVir/mainenv/local/lib/python2.7/site-packages/django/core/handlers/exception.py", line 41, in inner
    response = get_response(request)
  File "/home/haomao/pythonVir/mainenv/local/lib/python2.7/site-packages/django/core/handlers/base.py", line 249, in _legacy_get_response
    response = self._get_response(request)
  File "/home/haomao/pythonVir/mainenv/local/lib/python2.7/site-packages/django/core/handlers/base.py", line 198, in _get_response
    "returned None instead." % (callback.__module__, view_name)
ValueError: The view crawlermanage.views.settings didn't return an HttpResponse object. It returned None instead.
2017-08-31 18:46:01,737 [Thread-3:140701039847168] [django.request:152] [WARNING]- Not Found: /favicon.ico
2017-08-31 18:54:42,234 [Thread-12:140701006276352] [django.request:152] [WARNING]- Not Found: /favicon.ico
2017-08-31 18:55:24,426 [Thread-22:140700997883648] [django.request:152] [WARNING]- Not Found: /favicon.ico
2017-08-31 18:55:38,935 [Thread-23:140700997883648] [django.request:152] [WARNING]- Not Found: /favicon.ico
2017-08-31 19:14:30,751 [Thread-48:140701006276352] [django.request:152] [WARNING]- Not Found: /crawlermanage/debug/assets/bootstrap-table/src/extensions/editable/bootstrap-table-editable.js
2017-08-31 19:14:30,886 [Thread-49:140701006276352] [django.request:152] [WARNING]- Not Found: /crawlermanage/debug/assets/bootstrap-table/src/extensions/editable/bootstrap-table-editable.js
2017-08-31 20:39:47,355 [Thread-190:140701048239872] [django.request:152] [WARNING]- Not Found: /crawlermanage/lou
2017-08-31 20:39:52,864 [Thread-191:140701039847168] [django.request:152] [WARNING]- Not Found: /crawlermanage/layouit
2017-09-01 15:07:37,070 [Thread-3:140180787803904] [django.request:152] [WARNING]- Not Found: /favicon.ico
2017-09-01 17:00:33,134 [Thread-6:140027593131776] [django.request:135] [ERROR]- Internal Server Error: /crawlermanage/domainautocomplete/
Traceback (most recent call last):
  File "/home/haomao/pythonVir/mainenv/local/lib/python2.7/site-packages/django/core/handlers/exception.py", line 41, in inner
    response = get_response(request)
  File "/home/haomao/pythonVir/mainenv/local/lib/python2.7/site-packages/django/core/handlers/base.py", line 249, in _legacy_get_response
    response = self._get_response(request)
  File "/home/haomao/pythonVir/mainenv/local/lib/python2.7/site-packages/django/core/handlers/base.py", line 187, in _get_response
    response = self.process_exception_by_middleware(e, request)
  File "/home/haomao/pythonVir/mainenv/local/lib/python2.7/site-packages/django/core/handlers/base.py", line 185, in _get_response
    response = wrapped_callback(request, *callback_args, **callback_kwargs)
  File "/home/haomao/Desktop/project/geowind_crawler/crawlermanage/views.py", line 585, in domain_autocomplete
    return HttpResponse(json_resp,mimetype='application/json')
  File "/home/haomao/pythonVir/mainenv/local/lib/python2.7/site-packages/django/http/response.py", line 301, in __init__
    super(HttpResponse, self).__init__(*args, **kwargs)
TypeError: __init__() got an unexpected keyword argument 'mimetype'
2017-09-01 17:14:17,193 [Thread-4:140557730903808] [django.request:135] [ERROR]- Internal Server Error: /crawlermanage/domainautocomplete/
Traceback (most recent call last):
  File "/home/haomao/pythonVir/mainenv/local/lib/python2.7/site-packages/django/core/handlers/exception.py", line 41, in inner
    response = get_response(request)
  File "/home/haomao/pythonVir/mainenv/local/lib/python2.7/site-packages/django/core/handlers/base.py", line 249, in _legacy_get_response
    response = self._get_response(request)
  File "/home/haomao/pythonVir/mainenv/local/lib/python2.7/site-packages/django/core/handlers/base.py", line 187, in _get_response
    response = self.process_exception_by_middleware(e, request)
  File "/home/haomao/pythonVir/mainenv/local/lib/python2.7/site-packages/django/core/handlers/base.py", line 185, in _get_response
    response = wrapped_callback(request, *callback_args, **callback_kwargs)
  File "/home/haomao/Desktop/project/geowind_crawler/crawlermanage/views.py", line 594, in domain_autocomplete
    "Option 5"
  File "/home/haomao/pythonVir/mainenv/local/lib/python2.7/site-packages/django/core/serializers/__init__.py", line 129, in serialize
    s.serialize(queryset, **options)
  File "/home/haomao/pythonVir/mainenv/local/lib/python2.7/site-packages/django/core/serializers/base.py", line 84, in serialize
    concrete_model = obj._meta.concrete_model
AttributeError: 'str' object has no attribute '_meta'
2017-09-01 17:14:17,380 [Thread-5:140557730903808] [django.request:135] [ERROR]- Internal Server Error: /crawlermanage/domainautocomplete/
Traceback (most recent call last):
  File "/home/haomao/pythonVir/mainenv/local/lib/python2.7/site-packages/django/core/handlers/exception.py", line 41, in inner
    response = get_response(request)
  File "/home/haomao/pythonVir/mainenv/local/lib/python2.7/site-packages/django/core/handlers/base.py", line 249, in _legacy_get_response
    response = self._get_response(request)
  File "/home/haomao/pythonVir/mainenv/local/lib/python2.7/site-packages/django/core/handlers/base.py", line 187, in _get_response
    response = self.process_exception_by_middleware(e, request)
  File "/home/haomao/pythonVir/mainenv/local/lib/python2.7/site-packages/django/core/handlers/base.py", line 185, in _get_response
    response = wrapped_callback(request, *callback_args, **callback_kwargs)
  File "/home/haomao/Desktop/project/geowind_crawler/crawlermanage/views.py", line 594, in domain_autocomplete
    "Option 5"
  File "/home/haomao/pythonVir/mainenv/local/lib/python2.7/site-packages/django/core/serializers/__init__.py", line 129, in serialize
    s.serialize(queryset, **options)
  File "/home/haomao/pythonVir/mainenv/local/lib/python2.7/site-packages/django/core/serializers/base.py", line 84, in serialize
    concrete_model = obj._meta.concrete_model
AttributeError: 'str' object has no attribute '_meta'
2017-09-01 17:14:17,890 [Thread-6:140557730903808] [django.request:135] [ERROR]- Internal Server Error: /crawlermanage/domainautocomplete/
Traceback (most recent call last):
  File "/home/haomao/pythonVir/mainenv/local/lib/python2.7/site-packages/django/core/handlers/exception.py", line 41, in inner
    response = get_response(request)
  File "/home/haomao/pythonVir/mainenv/local/lib/python2.7/site-packages/django/core/handlers/base.py", line 249, in _legacy_get_response
    response = self._get_response(request)
  File "/home/haomao/pythonVir/mainenv/local/lib/python2.7/site-packages/django/core/handlers/base.py", line 187, in _get_response
    response = self.process_exception_by_middleware(e, request)
  File "/home/haomao/pythonVir/mainenv/local/lib/python2.7/site-packages/django/core/handlers/base.py", line 185, in _get_response
    response = wrapped_callback(request, *callback_args, **callback_kwargs)
  File "/home/haomao/Desktop/project/geowind_crawler/crawlermanage/views.py", line 594, in domain_autocomplete
    "Option 5"
  File "/home/haomao/pythonVir/mainenv/local/lib/python2.7/site-packages/django/core/serializers/__init__.py", line 129, in serialize
    s.serialize(queryset, **options)
  File "/home/haomao/pythonVir/mainenv/local/lib/python2.7/site-packages/django/core/serializers/base.py", line 84, in serialize
    concrete_model = obj._meta.concrete_model
AttributeError: 'str' object has no attribute '_meta'
2017-09-01 17:14:18,066 [Thread-7:140557730903808] [django.request:135] [ERROR]- Internal Server Error: /crawlermanage/domainautocomplete/
Traceback (most recent call last):
  File "/home/haomao/pythonVir/mainenv/local/lib/python2.7/site-packages/django/core/handlers/exception.py", line 41, in inner
    response = get_response(request)
  File "/home/haomao/pythonVir/mainenv/local/lib/python2.7/site-packages/django/core/handlers/base.py", line 249, in _legacy_get_response
    response = self._get_response(request)
  File "/home/haomao/pythonVir/mainenv/local/lib/python2.7/site-packages/django/core/handlers/base.py", line 187, in _get_response
    response = self.process_exception_by_middleware(e, request)
  File "/home/haomao/pythonVir/mainenv/local/lib/python2.7/site-packages/django/core/handlers/base.py", line 185, in _get_response
    response = wrapped_callback(request, *callback_args, **callback_kwargs)
  File "/home/haomao/Desktop/project/geowind_crawler/crawlermanage/views.py", line 594, in domain_autocomplete
    "Option 5"
  File "/home/haomao/pythonVir/mainenv/local/lib/python2.7/site-packages/django/core/serializers/__init__.py", line 129, in serialize
    s.serialize(queryset, **options)
  File "/home/haomao/pythonVir/mainenv/local/lib/python2.7/site-packages/django/core/serializers/base.py", line 84, in serialize
    concrete_model = obj._meta.concrete_model
AttributeError: 'str' object has no attribute '_meta'
2017-09-01 17:14:18,233 [Thread-8:140557730903808] [django.request:135] [ERROR]- Internal Server Error: /crawlermanage/domainautocomplete/
Traceback (most recent call last):
  File "/home/haomao/pythonVir/mainenv/local/lib/python2.7/site-packages/django/core/handlers/exception.py", line 41, in inner
    response = get_response(request)
  File "/home/haomao/pythonVir/mainenv/local/lib/python2.7/site-packages/django/core/handlers/base.py", line 249, in _legacy_get_response
    response = self._get_response(request)
  File "/home/haomao/pythonVir/mainenv/local/lib/python2.7/site-packages/django/core/handlers/base.py", line 187, in _get_response
    response = self.process_exception_by_middleware(e, request)
  File "/home/haomao/pythonVir/mainenv/local/lib/python2.7/site-packages/django/core/handlers/base.py", line 185, in _get_response
    response = wrapped_callback(request, *callback_args, **callback_kwargs)
  File "/home/haomao/Desktop/project/geowind_crawler/crawlermanage/views.py", line 594, in domain_autocomplete
    "Option 5"
  File "/home/haomao/pythonVir/mainenv/local/lib/python2.7/site-packages/django/core/serializers/__init__.py", line 129, in serialize
    s.serialize(queryset, **options)
  File "/home/haomao/pythonVir/mainenv/local/lib/python2.7/site-packages/django/core/serializers/base.py", line 84, in serialize
    concrete_model = obj._meta.concrete_model
AttributeError: 'str' object has no attribute '_meta'
2017-09-01 17:14:19,045 [Thread-9:140557730903808] [django.request:135] [ERROR]- Internal Server Error: /crawlermanage/domainautocomplete/
Traceback (most recent call last):
  File "/home/haomao/pythonVir/mainenv/local/lib/python2.7/site-packages/django/core/handlers/exception.py", line 41, in inner
    response = get_response(request)
  File "/home/haomao/pythonVir/mainenv/local/lib/python2.7/site-packages/django/core/handlers/base.py", line 249, in _legacy_get_response
    response = self._get_response(request)
  File "/home/haomao/pythonVir/mainenv/local/lib/python2.7/site-packages/django/core/handlers/base.py", line 187, in _get_response
    response = self.process_exception_by_middleware(e, request)
  File "/home/haomao/pythonVir/mainenv/local/lib/python2.7/site-packages/django/core/handlers/base.py", line 185, in _get_response
    response = wrapped_callback(request, *callback_args, **callback_kwargs)
  File "/home/haomao/Desktop/project/geowind_crawler/crawlermanage/views.py", line 594, in domain_autocomplete
    "Option 5"
  File "/home/haomao/pythonVir/mainenv/local/lib/python2.7/site-packages/django/core/serializers/__init__.py", line 129, in serialize
    s.serialize(queryset, **options)
  File "/home/haomao/pythonVir/mainenv/local/lib/python2.7/site-packages/django/core/serializers/base.py", line 84, in serialize
    concrete_model = obj._meta.concrete_model
AttributeError: 'str' object has no attribute '_meta'
2017-09-01 17:14:19,230 [Thread-10:140557730903808] [django.request:135] [ERROR]- Internal Server Error: /crawlermanage/domainautocomplete/
Traceback (most recent call last):
  File "/home/haomao/pythonVir/mainenv/local/lib/python2.7/site-packages/django/core/handlers/exception.py", line 41, in inner
    response = get_response(request)
  File "/home/haomao/pythonVir/mainenv/local/lib/python2.7/site-packages/django/core/handlers/base.py", line 249, in _legacy_get_response
    response = self._get_response(request)
  File "/home/haomao/pythonVir/mainenv/local/lib/python2.7/site-packages/django/core/handlers/base.py", line 187, in _get_response
    response = self.process_exception_by_middleware(e, request)
  File "/home/haomao/pythonVir/mainenv/local/lib/python2.7/site-packages/django/core/handlers/base.py", line 185, in _get_response
    response = wrapped_callback(request, *callback_args, **callback_kwargs)
  File "/home/haomao/Desktop/project/geowind_crawler/crawlermanage/views.py", line 594, in domain_autocomplete
    "Option 5"
  File "/home/haomao/pythonVir/mainenv/local/lib/python2.7/site-packages/django/core/serializers/__init__.py", line 129, in serialize
    s.serialize(queryset, **options)
  File "/home/haomao/pythonVir/mainenv/local/lib/python2.7/site-packages/django/core/serializers/base.py", line 84, in serialize
    concrete_model = obj._meta.concrete_model
AttributeError: 'str' object has no attribute '_meta'
2017-09-01 17:14:45,519 [Thread-4:140555335722752] [django.request:135] [ERROR]- Internal Server Error: /crawlermanage/domainautocomplete/
Traceback (most recent call last):
  File "/home/haomao/pythonVir/mainenv/local/lib/python2.7/site-packages/django/core/handlers/exception.py", line 41, in inner
    response = get_response(request)
  File "/home/haomao/pythonVir/mainenv/local/lib/python2.7/site-packages/django/core/handlers/base.py", line 249, in _legacy_get_response
    response = self._get_response(request)
  File "/home/haomao/pythonVir/mainenv/local/lib/python2.7/site-packages/django/core/handlers/base.py", line 187, in _get_response
    response = self.process_exception_by_middleware(e, request)
  File "/home/haomao/pythonVir/mainenv/local/lib/python2.7/site-packages/django/core/handlers/base.py", line 185, in _get_response
    response = wrapped_callback(request, *callback_args, **callback_kwargs)
  File "/home/haomao/Desktop/project/geowind_crawler/crawlermanage/views.py", line 594, in domain_autocomplete
    "Option 5"
  File "/home/haomao/pythonVir/mainenv/local/lib/python2.7/site-packages/django/core/serializers/__init__.py", line 129, in serialize
    s.serialize(queryset, **options)
  File "/home/haomao/pythonVir/mainenv/local/lib/python2.7/site-packages/django/core/serializers/base.py", line 84, in serialize
    concrete_model = obj._meta.concrete_model
AttributeError: 'str' object has no attribute '_meta'
2017-09-01 17:14:45,698 [Thread-5:140555335722752] [django.request:135] [ERROR]- Internal Server Error: /crawlermanage/domainautocomplete/
Traceback (most recent call last):
  File "/home/haomao/pythonVir/mainenv/local/lib/python2.7/site-packages/django/core/handlers/exception.py", line 41, in inner
    response = get_response(request)
  File "/home/haomao/pythonVir/mainenv/local/lib/python2.7/site-packages/django/core/handlers/base.py", line 249, in _legacy_get_response
    response = self._get_response(request)
  File "/home/haomao/pythonVir/mainenv/local/lib/python2.7/site-packages/django/core/handlers/base.py", line 187, in _get_response
    response = self.process_exception_by_middleware(e, request)
  File "/home/haomao/pythonVir/mainenv/local/lib/python2.7/site-packages/django/core/handlers/base.py", line 185, in _get_response
    response = wrapped_callback(request, *callback_args, **callback_kwargs)
  File "/home/haomao/Desktop/project/geowind_crawler/crawlermanage/views.py", line 594, in domain_autocomplete
    "Option 5"
  File "/home/haomao/pythonVir/mainenv/local/lib/python2.7/site-packages/django/core/serializers/__init__.py", line 129, in serialize
    s.serialize(queryset, **options)
  File "/home/haomao/pythonVir/mainenv/local/lib/python2.7/site-packages/django/core/serializers/base.py", line 84, in serialize
    concrete_model = obj._meta.concrete_model
AttributeError: 'str' object has no attribute '_meta'
2017-09-01 17:14:46,149 [Thread-6:140555335722752] [django.request:135] [ERROR]- Internal Server Error: /crawlermanage/domainautocomplete/
Traceback (most recent call last):
  File "/home/haomao/pythonVir/mainenv/local/lib/python2.7/site-packages/django/core/handlers/exception.py", line 41, in inner
    response = get_response(request)
  File "/home/haomao/pythonVir/mainenv/local/lib/python2.7/site-packages/django/core/handlers/base.py", line 249, in _legacy_get_response
    response = self._get_response(request)
  File "/home/haomao/pythonVir/mainenv/local/lib/python2.7/site-packages/django/core/handlers/base.py", line 187, in _get_response
    response = self.process_exception_by_middleware(e, request)
  File "/home/haomao/pythonVir/mainenv/local/lib/python2.7/site-packages/django/core/handlers/base.py", line 185, in _get_response
    response = wrapped_callback(request, *callback_args, **callback_kwargs)
  File "/home/haomao/Desktop/project/geowind_crawler/crawlermanage/views.py", line 594, in domain_autocomplete
    "Option 5"
  File "/home/haomao/pythonVir/mainenv/local/lib/python2.7/site-packages/django/core/serializers/__init__.py", line 129, in serialize
    s.serialize(queryset, **options)
  File "/home/haomao/pythonVir/mainenv/local/lib/python2.7/site-packages/django/core/serializers/base.py", line 84, in serialize
    concrete_model = obj._meta.concrete_model
AttributeError: 'str' object has no attribute '_meta'
2017-09-01 17:14:46,325 [Thread-7:140555335722752] [django.request:135] [ERROR]- Internal Server Error: /crawlermanage/domainautocomplete/
Traceback (most recent call last):
  File "/home/haomao/pythonVir/mainenv/local/lib/python2.7/site-packages/django/core/handlers/exception.py", line 41, in inner
    response = get_response(request)
  File "/home/haomao/pythonVir/mainenv/local/lib/python2.7/site-packages/django/core/handlers/base.py", line 249, in _legacy_get_response
    response = self._get_response(request)
  File "/home/haomao/pythonVir/mainenv/local/lib/python2.7/site-packages/django/core/handlers/base.py", line 187, in _get_response
    response = self.process_exception_by_middleware(e, request)
  File "/home/haomao/pythonVir/mainenv/local/lib/python2.7/site-packages/django/core/handlers/base.py", line 185, in _get_response
    response = wrapped_callback(request, *callback_args, **callback_kwargs)
  File "/home/haomao/Desktop/project/geowind_crawler/crawlermanage/views.py", line 594, in domain_autocomplete
    "Option 5"
  File "/home/haomao/pythonVir/mainenv/local/lib/python2.7/site-packages/django/core/serializers/__init__.py", line 129, in serialize
    s.serialize(queryset, **options)
  File "/home/haomao/pythonVir/mainenv/local/lib/python2.7/site-packages/django/core/serializers/base.py", line 84, in serialize
    concrete_model = obj._meta.concrete_model
AttributeError: 'str' object has no attribute '_meta'
2017-09-01 17:14:46,502 [Thread-8:140555335722752] [django.request:135] [ERROR]- Internal Server Error: /crawlermanage/domainautocomplete/
Traceback (most recent call last):
  File "/home/haomao/pythonVir/mainenv/local/lib/python2.7/site-packages/django/core/handlers/exception.py", line 41, in inner
    response = get_response(request)
  File "/home/haomao/pythonVir/mainenv/local/lib/python2.7/site-packages/django/core/handlers/base.py", line 249, in _legacy_get_response
    response = self._get_response(request)
  File "/home/haomao/pythonVir/mainenv/local/lib/python2.7/site-packages/django/core/handlers/base.py", line 187, in _get_response
    response = self.process_exception_by_middleware(e, request)
  File "/home/haomao/pythonVir/mainenv/local/lib/python2.7/site-packages/django/core/handlers/base.py", line 185, in _get_response
    response = wrapped_callback(request, *callback_args, **callback_kwargs)
  File "/home/haomao/Desktop/project/geowind_crawler/crawlermanage/views.py", line 594, in domain_autocomplete
    "Option 5"
  File "/home/haomao/pythonVir/mainenv/local/lib/python2.7/site-packages/django/core/serializers/__init__.py", line 129, in serialize
    s.serialize(queryset, **options)
  File "/home/haomao/pythonVir/mainenv/local/lib/python2.7/site-packages/django/core/serializers/base.py", line 84, in serialize
    concrete_model = obj._meta.concrete_model
AttributeError: 'str' object has no attribute '_meta'
2017-09-01 17:14:46,713 [Thread-9:140555335722752] [django.request:135] [ERROR]- Internal Server Error: /crawlermanage/domainautocomplete/
Traceback (most recent call last):
  File "/home/haomao/pythonVir/mainenv/local/lib/python2.7/site-packages/django/core/handlers/exception.py", line 41, in inner
    response = get_response(request)
  File "/home/haomao/pythonVir/mainenv/local/lib/python2.7/site-packages/django/core/handlers/base.py", line 249, in _legacy_get_response
    response = self._get_response(request)
  File "/home/haomao/pythonVir/mainenv/local/lib/python2.7/site-packages/django/core/handlers/base.py", line 187, in _get_response
    response = self.process_exception_by_middleware(e, request)
  File "/home/haomao/pythonVir/mainenv/local/lib/python2.7/site-packages/django/core/handlers/base.py", line 185, in _get_response
    response = wrapped_callback(request, *callback_args, **callback_kwargs)
  File "/home/haomao/Desktop/project/geowind_crawler/crawlermanage/views.py", line 594, in domain_autocomplete
    "Option 5"
  File "/home/haomao/pythonVir/mainenv/local/lib/python2.7/site-packages/django/core/serializers/__init__.py", line 129, in serialize
    s.serialize(queryset, **options)
  File "/home/haomao/pythonVir/mainenv/local/lib/python2.7/site-packages/django/core/serializers/base.py", line 84, in serialize
    concrete_model = obj._meta.concrete_model
AttributeError: 'str' object has no attribute '_meta'
2017-09-01 19:48:50,079 [Thread-71:140343642875648] [django.request:152] [WARNING]- Not Found: /crawlermanage/layout/aaa
2017-09-01 19:50:19,412 [Thread-75:140343642875648] [django.request:152] [WARNING]- Not Found: /crawlermanage/layout/www,jd.com
2017-09-01 19:50:48,487 [Thread-76:140343642875648] [django.request:152] [WARNING]- Not Found: /crawlermanage/layout/www,jd.com
2017-09-01 19:51:53,562 [Thread-78:140343642875648] [django.request:152] [WARNING]- Not Found: /crawlermanage/layout/www.taobao.com
